{"cells":[{"cell_type":"code","execution_count":21,"metadata":{"colab":{"base_uri":"https://localhost:8080/"},"executionInfo":{"elapsed":4899,"status":"ok","timestamp":1715733816531,"user":{"displayName":"Adithyaa seran","userId":"15600754421888670023"},"user_tz":-330},"id":"tw9UVx2AIKnN","outputId":"cdd4d7f2-0c9d-46e6-cdf1-a37d96ac71f0"},"outputs":[{"name":"stdout","output_type":"stream","text":["Mounted at /content/drive\n"]}],"source":["from google.colab import drive\n","drive.mount('/content/drive', force_remount=True)"]},{"cell_type":"code","execution_count":null,"metadata":{"colab":{"background_save":true,"base_uri":"https://localhost:8080/"},"id":"jcV2oCPVjreg"},"outputs":[{"name":"stderr","output_type":"stream","text":["ERROR:root:Internal Python error in the inspect module.\n","Below is the traceback from this internal error.\n","\n","ERROR:root:Internal Python error in the inspect module.\n","Below is the traceback from this internal error.\n","\n","ERROR:root:Internal Python error in the inspect module.\n","Below is the traceback from this internal error.\n","\n"]},{"name":"stdout","output_type":"stream","text":["Traceback (most recent call last):\n","  File \"/usr/local/lib/python3.10/dist-packages/IPython/core/interactiveshell.py\", line 3553, in run_code\n","    exec(code_obj, self.user_global_ns, self.user_ns)\n","  File \"\u003cipython-input-7-5b9e0b74ae45\u003e\", line 1, in \u003ccell line: 1\u003e\n","    get_ipython().run_line_magic('cd', '/content/drive/MyDrive/FYP_APRIL/Colour_correction')\n","  File \"/usr/local/lib/python3.10/dist-packages/IPython/core/interactiveshell.py\", line 2418, in run_line_magic\n","    result = fn(*args, **kwargs)\n","  File \"\u003cdecorator-gen-85\u003e\", line 2, in cd\n","  File \"/usr/local/lib/python3.10/dist-packages/IPython/core/magic.py\", line 187, in \u003clambda\u003e\n","    call = lambda f, *a, **k: f(*a, **k)\n","  File \"/usr/local/lib/python3.10/dist-packages/IPython/core/magics/osm.py\", line 342, in cd\n","    oldcwd = os.getcwd()\n","OSError: [Errno 107] Transport endpoint is not connected\n","\n","During handling of the above exception, another exception occurred:\n","\n","Traceback (most recent call last):\n","  File \"/usr/local/lib/python3.10/dist-packages/IPython/core/interactiveshell.py\", line 2099, in showtraceback\n","    stb = value._render_traceback_()\n","AttributeError: 'OSError' object has no attribute '_render_traceback_'\n","\n","During handling of the above exception, another exception occurred:\n","\n","Traceback (most recent call last):\n","  File \"/usr/local/lib/python3.10/dist-packages/IPython/core/ultratb.py\", line 1101, in get_records\n","    return _fixed_getinnerframes(etb, number_of_lines_of_context, tb_offset)\n","  File \"/usr/local/lib/python3.10/dist-packages/IPython/core/ultratb.py\", line 248, in wrapped\n","    return f(*args, **kwargs)\n","  File \"/usr/local/lib/python3.10/dist-packages/IPython/core/ultratb.py\", line 281, in _fixed_getinnerframes\n","    records = fix_frame_records_filenames(inspect.getinnerframes(etb, context))\n","  File \"/usr/lib/python3.10/inspect.py\", line 1662, in getinnerframes\n","    frameinfo = (tb.tb_frame,) + getframeinfo(tb, context)\n","  File \"/usr/lib/python3.10/inspect.py\", line 1620, in getframeinfo\n","    filename = getsourcefile(frame) or getfile(frame)\n","  File \"/usr/lib/python3.10/inspect.py\", line 829, in getsourcefile\n","    module = getmodule(object, filename)\n","  File \"/usr/lib/python3.10/inspect.py\", line 861, in getmodule\n","    file = getabsfile(object, _filename)\n","  File \"/usr/lib/python3.10/inspect.py\", line 845, in getabsfile\n","    return os.path.normcase(os.path.abspath(_filename))\n","  File \"/usr/lib/python3.10/posixpath.py\", line 384, in abspath\n","    cwd = os.getcwd()\n","OSError: [Errno 107] Transport endpoint is not connected\n","Traceback (most recent call last):\n","  File \"/usr/local/lib/python3.10/dist-packages/IPython/core/interactiveshell.py\", line 3553, in run_code\n","    exec(code_obj, self.user_global_ns, self.user_ns)\n","  File \"\u003cipython-input-7-5b9e0b74ae45\u003e\", line 1, in \u003ccell line: 1\u003e\n","    get_ipython().run_line_magic('cd', '/content/drive/MyDrive/FYP_APRIL/Colour_correction')\n","  File \"/usr/local/lib/python3.10/dist-packages/IPython/core/interactiveshell.py\", line 2418, in run_line_magic\n","    result = fn(*args, **kwargs)\n","  File \"\u003cdecorator-gen-85\u003e\", line 2, in cd\n","  File \"/usr/local/lib/python3.10/dist-packages/IPython/core/magic.py\", line 187, in \u003clambda\u003e\n","    call = lambda f, *a, **k: f(*a, **k)\n","  File \"/usr/local/lib/python3.10/dist-packages/IPython/core/magics/osm.py\", line 342, in cd\n","    oldcwd = os.getcwd()\n","OSError: [Errno 107] Transport endpoint is not connected\n","\n","During handling of the above exception, another exception occurred:\n","\n","Traceback (most recent call last):\n","  File \"/usr/local/lib/python3.10/dist-packages/IPython/core/interactiveshell.py\", line 2099, in showtraceback\n","    stb = value._render_traceback_()\n","AttributeError: 'OSError' object has no attribute '_render_traceback_'\n","\n","During handling of the above exception, another exception occurred:\n","\n","Traceback (most recent call last):\n","  File \"/usr/local/lib/python3.10/dist-packages/IPython/core/interactiveshell.py\", line 3473, in run_ast_nodes\n","    if (await self.run_code(code, result,  async_=asy)):\n","  File \"/usr/local/lib/python3.10/dist-packages/IPython/core/interactiveshell.py\", line 3575, in run_code\n","    self.showtraceback(running_compiled_code=True)\n","  File \"/usr/local/lib/python3.10/dist-packages/IPython/core/interactiveshell.py\", line 2101, in showtraceback\n","    stb = self.InteractiveTB.structured_traceback(etype,\n","  File \"/usr/local/lib/python3.10/dist-packages/IPython/core/ultratb.py\", line 1367, in structured_traceback\n","    return FormattedTB.structured_traceback(\n","  File \"/usr/local/lib/python3.10/dist-packages/IPython/core/ultratb.py\", line 1267, in structured_traceback\n","    return VerboseTB.structured_traceback(\n","  File \"/usr/local/lib/python3.10/dist-packages/IPython/core/ultratb.py\", line 1124, in structured_traceback\n","    formatted_exception = self.format_exception_as_a_whole(etype, evalue, etb, number_of_lines_of_context,\n","  File \"/usr/local/lib/python3.10/dist-packages/IPython/core/ultratb.py\", line 1082, in format_exception_as_a_whole\n","    last_unique, recursion_repeat = find_recursion(orig_etype, evalue, records)\n","  File \"/usr/local/lib/python3.10/dist-packages/IPython/core/ultratb.py\", line 382, in find_recursion\n","    return len(records), 0\n","TypeError: object of type 'NoneType' has no len()\n","\n","During handling of the above exception, another exception occurred:\n","\n","Traceback (most recent call last):\n","  File \"/usr/local/lib/python3.10/dist-packages/IPython/core/interactiveshell.py\", line 2099, in showtraceback\n","    stb = value._render_traceback_()\n","AttributeError: 'TypeError' object has no attribute '_render_traceback_'\n","\n","During handling of the above exception, another exception occurred:\n","\n","Traceback (most recent call last):\n","  File \"/usr/local/lib/python3.10/dist-packages/IPython/core/ultratb.py\", line 1101, in get_records\n","    return _fixed_getinnerframes(etb, number_of_lines_of_context, tb_offset)\n","  File \"/usr/local/lib/python3.10/dist-packages/IPython/core/ultratb.py\", line 248, in wrapped\n","    return f(*args, **kwargs)\n","  File \"/usr/local/lib/python3.10/dist-packages/IPython/core/ultratb.py\", line 281, in _fixed_getinnerframes\n","    records = fix_frame_records_filenames(inspect.getinnerframes(etb, context))\n","  File \"/usr/lib/python3.10/inspect.py\", line 1662, in getinnerframes\n","    frameinfo = (tb.tb_frame,) + getframeinfo(tb, context)\n","  File \"/usr/lib/python3.10/inspect.py\", line 1620, in getframeinfo\n","    filename = getsourcefile(frame) or getfile(frame)\n","  File \"/usr/lib/python3.10/inspect.py\", line 829, in getsourcefile\n","    module = getmodule(object, filename)\n","  File \"/usr/lib/python3.10/inspect.py\", line 861, in getmodule\n","    file = getabsfile(object, _filename)\n","  File \"/usr/lib/python3.10/inspect.py\", line 845, in getabsfile\n","    return os.path.normcase(os.path.abspath(_filename))\n","  File \"/usr/lib/python3.10/posixpath.py\", line 384, in abspath\n","    cwd = os.getcwd()\n","OSError: [Errno 107] Transport endpoint is not connected\n","Traceback (most recent call last):\n","  File \"/usr/local/lib/python3.10/dist-packages/IPython/core/interactiveshell.py\", line 3553, in run_code\n","    exec(code_obj, self.user_global_ns, self.user_ns)\n","  File \"\u003cipython-input-7-5b9e0b74ae45\u003e\", line 1, in \u003ccell line: 1\u003e\n","    get_ipython().run_line_magic('cd', '/content/drive/MyDrive/FYP_APRIL/Colour_correction')\n","  File \"/usr/local/lib/python3.10/dist-packages/IPython/core/interactiveshell.py\", line 2418, in run_line_magic\n","    result = fn(*args, **kwargs)\n","  File \"\u003cdecorator-gen-85\u003e\", line 2, in cd\n","  File \"/usr/local/lib/python3.10/dist-packages/IPython/core/magic.py\", line 187, in \u003clambda\u003e\n","    call = lambda f, *a, **k: f(*a, **k)\n","  File \"/usr/local/lib/python3.10/dist-packages/IPython/core/magics/osm.py\", line 342, in cd\n","    oldcwd = os.getcwd()\n","OSError: [Errno 107] Transport endpoint is not connected\n","\n","During handling of the above exception, another exception occurred:\n","\n","Traceback (most recent call last):\n","  File \"/usr/local/lib/python3.10/dist-packages/IPython/core/interactiveshell.py\", line 2099, in showtraceback\n","    stb = value._render_traceback_()\n","AttributeError: 'OSError' object has no attribute '_render_traceback_'\n","\n","During handling of the above exception, another exception occurred:\n","\n","Traceback (most recent call last):\n","  File \"/usr/local/lib/python3.10/dist-packages/IPython/core/interactiveshell.py\", line 3473, in run_ast_nodes\n","    if (await self.run_code(code, result,  async_=asy)):\n","  File \"/usr/local/lib/python3.10/dist-packages/IPython/core/interactiveshell.py\", line 3575, in run_code\n","    self.showtraceback(running_compiled_code=True)\n","  File \"/usr/local/lib/python3.10/dist-packages/IPython/core/interactiveshell.py\", line 2101, in showtraceback\n","    stb = self.InteractiveTB.structured_traceback(etype,\n","  File \"/usr/local/lib/python3.10/dist-packages/IPython/core/ultratb.py\", line 1367, in structured_traceback\n","    return FormattedTB.structured_traceback(\n","  File \"/usr/local/lib/python3.10/dist-packages/IPython/core/ultratb.py\", line 1267, in structured_traceback\n","    return VerboseTB.structured_traceback(\n","  File \"/usr/local/lib/python3.10/dist-packages/IPython/core/ultratb.py\", line 1124, in structured_traceback\n","    formatted_exception = self.format_exception_as_a_whole(etype, evalue, etb, number_of_lines_of_context,\n","  File \"/usr/local/lib/python3.10/dist-packages/IPython/core/ultratb.py\", line 1082, in format_exception_as_a_whole\n","    last_unique, recursion_repeat = find_recursion(orig_etype, evalue, records)\n","  File \"/usr/local/lib/python3.10/dist-packages/IPython/core/ultratb.py\", line 382, in find_recursion\n","    return len(records), 0\n","TypeError: object of type 'NoneType' has no len()\n","\n","During handling of the above exception, another exception occurred:\n","\n","Traceback (most recent call last):\n","  File \"/usr/local/lib/python3.10/dist-packages/IPython/core/interactiveshell.py\", line 2099, in showtraceback\n","    stb = value._render_traceback_()\n","AttributeError: 'TypeError' object has no attribute '_render_traceback_'\n","\n","During handling of the above exception, another exception occurred:\n","\n","Traceback (most recent call last):\n","  File \"/usr/local/lib/python3.10/dist-packages/IPython/core/interactiveshell.py\", line 3030, in _run_cell\n","    return runner(coro)\n","  File \"/usr/local/lib/python3.10/dist-packages/IPython/core/async_helpers.py\", line 78, in _pseudo_sync_runner\n","    coro.send(None)\n","  File \"/usr/local/lib/python3.10/dist-packages/IPython/core/interactiveshell.py\", line 3257, in run_cell_async\n","    has_raised = await self.run_ast_nodes(code_ast.body, cell_name,\n","  File \"/usr/local/lib/python3.10/dist-packages/IPython/core/interactiveshell.py\", line 3492, in run_ast_nodes\n","    self.showtraceback()\n","  File \"/usr/local/lib/python3.10/dist-packages/IPython/core/interactiveshell.py\", line 2101, in showtraceback\n","    stb = self.InteractiveTB.structured_traceback(etype,\n","  File \"/usr/local/lib/python3.10/dist-packages/IPython/core/ultratb.py\", line 1367, in structured_traceback\n","    return FormattedTB.structured_traceback(\n","  File \"/usr/local/lib/python3.10/dist-packages/IPython/core/ultratb.py\", line 1267, in structured_traceback\n","    return VerboseTB.structured_traceback(\n","  File \"/usr/local/lib/python3.10/dist-packages/IPython/core/ultratb.py\", line 1142, in structured_traceback\n","    formatted_exceptions += self.format_exception_as_a_whole(etype, evalue, etb, lines_of_context,\n","  File \"/usr/local/lib/python3.10/dist-packages/IPython/core/ultratb.py\", line 1082, in format_exception_as_a_whole\n","    last_unique, recursion_repeat = find_recursion(orig_etype, evalue, records)\n","  File \"/usr/local/lib/python3.10/dist-packages/IPython/core/ultratb.py\", line 382, in find_recursion\n","    return len(records), 0\n","TypeError: object of type 'NoneType' has no len()\n","\n","During handling of the above exception, another exception occurred:\n","\n","Traceback (most recent call last):\n","  File \"/usr/local/lib/python3.10/dist-packages/IPython/core/interactiveshell.py\", line 2099, in showtraceback\n","    stb = value._render_traceback_()\n","AttributeError: 'TypeError' object has no attribute '_render_traceback_'\n","\n","During handling of the above exception, another exception occurred:\n","\n","Traceback (most recent call last):\n","  File \"/usr/local/lib/python3.10/dist-packages/IPython/core/ultratb.py\", line 1101, in get_records\n","    return _fixed_getinnerframes(etb, number_of_lines_of_context, tb_offset)\n","  File \"/usr/local/lib/python3.10/dist-packages/IPython/core/ultratb.py\", line 248, in wrapped\n","    return f(*args, **kwargs)\n","  File \"/usr/local/lib/python3.10/dist-packages/IPython/core/ultratb.py\", line 281, in _fixed_getinnerframes\n","    records = fix_frame_records_filenames(inspect.getinnerframes(etb, context))\n","  File \"/usr/lib/python3.10/inspect.py\", line 1662, in getinnerframes\n","    frameinfo = (tb.tb_frame,) + getframeinfo(tb, context)\n","  File \"/usr/lib/python3.10/inspect.py\", line 1620, in getframeinfo\n","    filename = getsourcefile(frame) or getfile(frame)\n","  File \"/usr/lib/python3.10/inspect.py\", line 829, in getsourcefile\n","    module = getmodule(object, filename)\n","  File \"/usr/lib/python3.10/inspect.py\", line 861, in getmodule\n","    file = getabsfile(object, _filename)\n","  File \"/usr/lib/python3.10/inspect.py\", line 845, in getabsfile\n","    return os.path.normcase(os.path.abspath(_filename))\n","  File \"/usr/lib/python3.10/posixpath.py\", line 384, in abspath\n","    cwd = os.getcwd()\n","OSError: [Errno 107] Transport endpoint is not connected\n"]}],"source":["%cd /content/drive/MyDrive/FYP_APRIL/Colour_correction"]},{"cell_type":"code","execution_count":22,"metadata":{"colab":{"base_uri":"https://localhost:8080/"},"executionInfo":{"elapsed":34,"status":"ok","timestamp":1715733816532,"user":{"displayName":"Adithyaa seran","userId":"15600754421888670023"},"user_tz":-330},"id":"YkTw8_FpL1sy","outputId":"e3237482-2315-4616-e04e-d157adfc03a0"},"outputs":[{"name":"stdout","output_type":"stream","text":["shell-init: error retrieving current directory: getcwd: cannot access parent directories: Transport endpoint is not connected\n","shell-init: error retrieving current directory: getcwd: cannot access parent directories: Transport endpoint is not connected\n","python3: can't open file 'test.py': [Errno 107] Transport endpoint is not connected\n"]}],"source":["!python test.py"]},{"cell_type":"code","execution_count":null,"metadata":{"colab":{"background_save":true,"base_uri":"https://localhost:8080/"},"id":"aLvEuPpEMIWR"},"outputs":[{"name":"stderr","output_type":"stream","text":["ERROR:root:Internal Python error in the inspect module.\n","Below is the traceback from this internal error.\n","\n"]},{"name":"stdout","output_type":"stream","text":["Traceback (most recent call last):\n","  File \"/usr/local/lib/python3.10/dist-packages/IPython/core/interactiveshell.py\", line 3553, in run_code\n","    exec(code_obj, self.user_global_ns, self.user_ns)\n","  File \"\u003cipython-input-23-8f7e8a29bfb4\u003e\", line 3, in \u003ccell line: 3\u003e\n","    from skimage import io\n","  File \"\u003cfrozen importlib._bootstrap\u003e\", line 1027, in _find_and_load\n","  File \"\u003cfrozen importlib._bootstrap\u003e\", line 1002, in _find_and_load_unlocked\n","  File \"\u003cfrozen importlib._bootstrap\u003e\", line 945, in _find_spec\n","  File \"\u003cfrozen importlib._bootstrap_external\u003e\", line 1439, in find_spec\n","  File \"\u003cfrozen importlib._bootstrap_external\u003e\", line 1408, in _get_spec\n","  File \"\u003cfrozen importlib._bootstrap_external\u003e\", line 1366, in _path_importer_cache\n","OSError: [Errno 107] Transport endpoint is not connected\n","\n","During handling of the above exception, another exception occurred:\n","\n","Traceback (most recent call last):\n","  File \"/usr/local/lib/python3.10/dist-packages/IPython/core/interactiveshell.py\", line 2099, in showtraceback\n","    stb = value._render_traceback_()\n","AttributeError: 'OSError' object has no attribute '_render_traceback_'\n","\n","During handling of the above exception, another exception occurred:\n","\n","Traceback (most recent call last):\n","  File \"/usr/local/lib/python3.10/dist-packages/IPython/core/ultratb.py\", line 1101, in get_records\n","    return _fixed_getinnerframes(etb, number_of_lines_of_context, tb_offset)\n","  File \"/usr/local/lib/python3.10/dist-packages/IPython/core/ultratb.py\", line 248, in wrapped\n","    return f(*args, **kwargs)\n","  File \"/usr/local/lib/python3.10/dist-packages/IPython/core/ultratb.py\", line 281, in _fixed_getinnerframes\n","    records = fix_frame_records_filenames(inspect.getinnerframes(etb, context))\n","  File \"/usr/lib/python3.10/inspect.py\", line 1662, in getinnerframes\n","    frameinfo = (tb.tb_frame,) + getframeinfo(tb, context)\n","  File \"/usr/lib/python3.10/inspect.py\", line 1620, in getframeinfo\n","    filename = getsourcefile(frame) or getfile(frame)\n","  File \"/usr/lib/python3.10/inspect.py\", line 829, in getsourcefile\n","    module = getmodule(object, filename)\n","  File \"/usr/lib/python3.10/inspect.py\", line 861, in getmodule\n","    file = getabsfile(object, _filename)\n","  File \"/usr/lib/python3.10/inspect.py\", line 845, in getabsfile\n","    return os.path.normcase(os.path.abspath(_filename))\n","  File \"/usr/lib/python3.10/posixpath.py\", line 384, in abspath\n","    cwd = os.getcwd()\n","OSError: [Errno 107] Transport endpoint is not connected\n"]},{"name":"stderr","output_type":"stream","text":["ERROR:root:Internal Python error in the inspect module.\n","Below is the traceback from this internal error.\n","\n"]},{"name":"stdout","output_type":"stream","text":["Traceback (most recent call last):\n","  File \"/usr/local/lib/python3.10/dist-packages/IPython/core/interactiveshell.py\", line 3553, in run_code\n","    exec(code_obj, self.user_global_ns, self.user_ns)\n","  File \"\u003cipython-input-23-8f7e8a29bfb4\u003e\", line 3, in \u003ccell line: 3\u003e\n","    from skimage import io\n","  File \"\u003cfrozen importlib._bootstrap\u003e\", line 1027, in _find_and_load\n","  File \"\u003cfrozen importlib._bootstrap\u003e\", line 1002, in _find_and_load_unlocked\n","  File \"\u003cfrozen importlib._bootstrap\u003e\", line 945, in _find_spec\n","  File \"\u003cfrozen importlib._bootstrap_external\u003e\", line 1439, in find_spec\n","  File \"\u003cfrozen importlib._bootstrap_external\u003e\", line 1408, in _get_spec\n","  File \"\u003cfrozen importlib._bootstrap_external\u003e\", line 1366, in _path_importer_cache\n","OSError: [Errno 107] Transport endpoint is not connected\n","\n","During handling of the above exception, another exception occurred:\n","\n","Traceback (most recent call last):\n","  File \"/usr/local/lib/python3.10/dist-packages/IPython/core/interactiveshell.py\", line 2099, in showtraceback\n","    stb = value._render_traceback_()\n","AttributeError: 'OSError' object has no attribute '_render_traceback_'\n","\n","During handling of the above exception, another exception occurred:\n","\n","Traceback (most recent call last):\n","  File \"/usr/local/lib/python3.10/dist-packages/IPython/core/interactiveshell.py\", line 3473, in run_ast_nodes\n","    if (await self.run_code(code, result,  async_=asy)):\n","  File \"/usr/local/lib/python3.10/dist-packages/IPython/core/interactiveshell.py\", line 3575, in run_code\n","    self.showtraceback(running_compiled_code=True)\n","  File \"/usr/local/lib/python3.10/dist-packages/IPython/core/interactiveshell.py\", line 2101, in showtraceback\n","    stb = self.InteractiveTB.structured_traceback(etype,\n","  File \"/usr/local/lib/python3.10/dist-packages/IPython/core/ultratb.py\", line 1367, in structured_traceback\n","    return FormattedTB.structured_traceback(\n","  File \"/usr/local/lib/python3.10/dist-packages/IPython/core/ultratb.py\", line 1267, in structured_traceback\n","    return VerboseTB.structured_traceback(\n","  File \"/usr/local/lib/python3.10/dist-packages/IPython/core/ultratb.py\", line 1124, in structured_traceback\n","    formatted_exception = self.format_exception_as_a_whole(etype, evalue, etb, number_of_lines_of_context,\n","  File \"/usr/local/lib/python3.10/dist-packages/IPython/core/ultratb.py\", line 1082, in format_exception_as_a_whole\n","    last_unique, recursion_repeat = find_recursion(orig_etype, evalue, records)\n","  File \"/usr/local/lib/python3.10/dist-packages/IPython/core/ultratb.py\", line 382, in find_recursion\n","    return len(records), 0\n","TypeError: object of type 'NoneType' has no len()\n","\n","During handling of the above exception, another exception occurred:\n","\n","Traceback (most recent call last):\n","  File \"/usr/local/lib/python3.10/dist-packages/IPython/core/interactiveshell.py\", line 2099, in showtraceback\n","    stb = value._render_traceback_()\n","AttributeError: 'TypeError' object has no attribute '_render_traceback_'\n","\n","During handling of the above exception, another exception occurred:\n","\n","Traceback (most recent call last):\n","  File \"/usr/local/lib/python3.10/dist-packages/IPython/core/ultratb.py\", line 1101, in get_records\n","    return _fixed_getinnerframes(etb, number_of_lines_of_context, tb_offset)\n","  File \"/usr/local/lib/python3.10/dist-packages/IPython/core/ultratb.py\", line 248, in wrapped\n","    return f(*args, **kwargs)\n","  File \"/usr/local/lib/python3.10/dist-packages/IPython/core/ultratb.py\", line 281, in _fixed_getinnerframes\n","    records = fix_frame_records_filenames(inspect.getinnerframes(etb, context))\n","  File \"/usr/lib/python3.10/inspect.py\", line 1662, in getinnerframes\n","    frameinfo = (tb.tb_frame,) + getframeinfo(tb, context)\n","  File \"/usr/lib/python3.10/inspect.py\", line 1620, in getframeinfo\n","    filename = getsourcefile(frame) or getfile(frame)\n","  File \"/usr/lib/python3.10/inspect.py\", line 829, in getsourcefile\n","    module = getmodule(object, filename)\n","  File \"/usr/lib/python3.10/inspect.py\", line 861, in getmodule\n","    file = getabsfile(object, _filename)\n","  File \"/usr/lib/python3.10/inspect.py\", line 845, in getabsfile\n","    return os.path.normcase(os.path.abspath(_filename))\n","  File \"/usr/lib/python3.10/posixpath.py\", line 384, in abspath\n","    cwd = os.getcwd()\n","OSError: [Errno 107] Transport endpoint is not connected\n"]},{"name":"stderr","output_type":"stream","text":["ERROR:root:Internal Python error in the inspect module.\n","Below is the traceback from this internal error.\n","\n"]},{"name":"stdout","output_type":"stream","text":["Traceback (most recent call last):\n","  File \"/usr/local/lib/python3.10/dist-packages/IPython/core/interactiveshell.py\", line 3553, in run_code\n","    exec(code_obj, self.user_global_ns, self.user_ns)\n","  File \"\u003cipython-input-23-8f7e8a29bfb4\u003e\", line 3, in \u003ccell line: 3\u003e\n","    from skimage import io\n","  File \"\u003cfrozen importlib._bootstrap\u003e\", line 1027, in _find_and_load\n","  File \"\u003cfrozen importlib._bootstrap\u003e\", line 1002, in _find_and_load_unlocked\n","  File \"\u003cfrozen importlib._bootstrap\u003e\", line 945, in _find_spec\n","  File \"\u003cfrozen importlib._bootstrap_external\u003e\", line 1439, in find_spec\n","  File \"\u003cfrozen importlib._bootstrap_external\u003e\", line 1408, in _get_spec\n","  File \"\u003cfrozen importlib._bootstrap_external\u003e\", line 1366, in _path_importer_cache\n","OSError: [Errno 107] Transport endpoint is not connected\n","\n","During handling of the above exception, another exception occurred:\n","\n","Traceback (most recent call last):\n","  File \"/usr/local/lib/python3.10/dist-packages/IPython/core/interactiveshell.py\", line 2099, in showtraceback\n","    stb = value._render_traceback_()\n","AttributeError: 'OSError' object has no attribute '_render_traceback_'\n","\n","During handling of the above exception, another exception occurred:\n","\n","Traceback (most recent call last):\n","  File \"/usr/local/lib/python3.10/dist-packages/IPython/core/interactiveshell.py\", line 3473, in run_ast_nodes\n","    if (await self.run_code(code, result,  async_=asy)):\n","  File \"/usr/local/lib/python3.10/dist-packages/IPython/core/interactiveshell.py\", line 3575, in run_code\n","    self.showtraceback(running_compiled_code=True)\n","  File \"/usr/local/lib/python3.10/dist-packages/IPython/core/interactiveshell.py\", line 2101, in showtraceback\n","    stb = self.InteractiveTB.structured_traceback(etype,\n","  File \"/usr/local/lib/python3.10/dist-packages/IPython/core/ultratb.py\", line 1367, in structured_traceback\n","    return FormattedTB.structured_traceback(\n","  File \"/usr/local/lib/python3.10/dist-packages/IPython/core/ultratb.py\", line 1267, in structured_traceback\n","    return VerboseTB.structured_traceback(\n","  File \"/usr/local/lib/python3.10/dist-packages/IPython/core/ultratb.py\", line 1124, in structured_traceback\n","    formatted_exception = self.format_exception_as_a_whole(etype, evalue, etb, number_of_lines_of_context,\n","  File \"/usr/local/lib/python3.10/dist-packages/IPython/core/ultratb.py\", line 1082, in format_exception_as_a_whole\n","    last_unique, recursion_repeat = find_recursion(orig_etype, evalue, records)\n","  File \"/usr/local/lib/python3.10/dist-packages/IPython/core/ultratb.py\", line 382, in find_recursion\n","    return len(records), 0\n","TypeError: object of type 'NoneType' has no len()\n","\n","During handling of the above exception, another exception occurred:\n","\n","Traceback (most recent call last):\n","  File \"/usr/local/lib/python3.10/dist-packages/IPython/core/interactiveshell.py\", line 2099, in showtraceback\n","    stb = value._render_traceback_()\n","AttributeError: 'TypeError' object has no attribute '_render_traceback_'\n","\n","During handling of the above exception, another exception occurred:\n","\n","Traceback (most recent call last):\n","  File \"/usr/local/lib/python3.10/dist-packages/IPython/core/interactiveshell.py\", line 3030, in _run_cell\n","    return runner(coro)\n","  File \"/usr/local/lib/python3.10/dist-packages/IPython/core/async_helpers.py\", line 78, in _pseudo_sync_runner\n","    coro.send(None)\n","  File \"/usr/local/lib/python3.10/dist-packages/IPython/core/interactiveshell.py\", line 3257, in run_cell_async\n","    has_raised = await self.run_ast_nodes(code_ast.body, cell_name,\n","  File \"/usr/local/lib/python3.10/dist-packages/IPython/core/interactiveshell.py\", line 3492, in run_ast_nodes\n","    self.showtraceback()\n","  File \"/usr/local/lib/python3.10/dist-packages/IPython/core/interactiveshell.py\", line 2101, in showtraceback\n","    stb = self.InteractiveTB.structured_traceback(etype,\n","  File \"/usr/local/lib/python3.10/dist-packages/IPython/core/ultratb.py\", line 1367, in structured_traceback\n","    return FormattedTB.structured_traceback(\n","  File \"/usr/local/lib/python3.10/dist-packages/IPython/core/ultratb.py\", line 1267, in structured_traceback\n","    return VerboseTB.structured_traceback(\n","  File \"/usr/local/lib/python3.10/dist-packages/IPython/core/ultratb.py\", line 1142, in structured_traceback\n","    formatted_exceptions += self.format_exception_as_a_whole(etype, evalue, etb, lines_of_context,\n","  File \"/usr/local/lib/python3.10/dist-packages/IPython/core/ultratb.py\", line 1082, in format_exception_as_a_whole\n","    last_unique, recursion_repeat = find_recursion(orig_etype, evalue, records)\n","  File \"/usr/local/lib/python3.10/dist-packages/IPython/core/ultratb.py\", line 382, in find_recursion\n","    return len(records), 0\n","TypeError: object of type 'NoneType' has no len()\n","\n","During handling of the above exception, another exception occurred:\n","\n","Traceback (most recent call last):\n","  File \"/usr/local/lib/python3.10/dist-packages/IPython/core/interactiveshell.py\", line 2099, in showtraceback\n","    stb = value._render_traceback_()\n","AttributeError: 'TypeError' object has no attribute '_render_traceback_'\n","\n","During handling of the above exception, another exception occurred:\n","\n","Traceback (most recent call last):\n","  File \"/usr/local/lib/python3.10/dist-packages/IPython/core/ultratb.py\", line 1101, in get_records\n","    return _fixed_getinnerframes(etb, number_of_lines_of_context, tb_offset)\n","  File \"/usr/local/lib/python3.10/dist-packages/IPython/core/ultratb.py\", line 248, in wrapped\n","    return f(*args, **kwargs)\n","  File \"/usr/local/lib/python3.10/dist-packages/IPython/core/ultratb.py\", line 281, in _fixed_getinnerframes\n","    records = fix_frame_records_filenames(inspect.getinnerframes(etb, context))\n","  File \"/usr/lib/python3.10/inspect.py\", line 1662, in getinnerframes\n","    frameinfo = (tb.tb_frame,) + getframeinfo(tb, context)\n","  File \"/usr/lib/python3.10/inspect.py\", line 1620, in getframeinfo\n","    filename = getsourcefile(frame) or getfile(frame)\n","  File \"/usr/lib/python3.10/inspect.py\", line 829, in getsourcefile\n","    module = getmodule(object, filename)\n","  File \"/usr/lib/python3.10/inspect.py\", line 861, in getmodule\n","    file = getabsfile(object, _filename)\n","  File \"/usr/lib/python3.10/inspect.py\", line 845, in getabsfile\n","    return os.path.normcase(os.path.abspath(_filename))\n","  File \"/usr/lib/python3.10/posixpath.py\", line 384, in abspath\n","    cwd = os.getcwd()\n","OSError: [Errno 107] Transport endpoint is not connected\n"]}],"source":["from google.colab.patches import cv2_imshow # for image display\n","# for reading the images\n","from skimage import io\n","import cv2 as cv\n","\n","# read and display the degraded image first\n","image = io.imread('./hazy_test/0.jpg')\n","image_2 = cv.cvtColor(image, cv.COLOR_BGR2RGB)\n","cv2_imshow(image_2)\n"]},{"cell_type":"code","execution_count":null,"metadata":{"colab":{"background_save":true,"base_uri":"https://localhost:8080/"},"id":"skOqAj5jNJYd"},"outputs":[{"name":"stderr","output_type":"stream","text":["ERROR:root:Internal Python error in the inspect module.\n","Below is the traceback from this internal error.\n","\n","ERROR:root:Internal Python error in the inspect module.\n","Below is the traceback from this internal error.\n","\n","ERROR:root:Internal Python error in the inspect module.\n","Below is the traceback from this internal error.\n","\n"]},{"name":"stdout","output_type":"stream","text":["Traceback (most recent call last):\n","  File \"/usr/local/lib/python3.10/dist-packages/IPython/core/interactiveshell.py\", line 3553, in run_code\n","    exec(code_obj, self.user_global_ns, self.user_ns)\n","  File \"\u003cipython-input-23-8dadbe3f0a94\u003e\", line 2, in \u003ccell line: 2\u003e\n","    image = io.imread('./facades/Ours_UIEB/0.jpg')\n","NameError: name 'io' is not defined\n","\n","During handling of the above exception, another exception occurred:\n","\n","Traceback (most recent call last):\n","  File \"/usr/local/lib/python3.10/dist-packages/IPython/core/interactiveshell.py\", line 2099, in showtraceback\n","    stb = value._render_traceback_()\n","AttributeError: 'NameError' object has no attribute '_render_traceback_'\n","\n","During handling of the above exception, another exception occurred:\n","\n","Traceback (most recent call last):\n","  File \"/usr/local/lib/python3.10/dist-packages/IPython/core/ultratb.py\", line 1101, in get_records\n","    return _fixed_getinnerframes(etb, number_of_lines_of_context, tb_offset)\n","  File \"/usr/local/lib/python3.10/dist-packages/IPython/core/ultratb.py\", line 248, in wrapped\n","    return f(*args, **kwargs)\n","  File \"/usr/local/lib/python3.10/dist-packages/IPython/core/ultratb.py\", line 281, in _fixed_getinnerframes\n","    records = fix_frame_records_filenames(inspect.getinnerframes(etb, context))\n","  File \"/usr/lib/python3.10/inspect.py\", line 1662, in getinnerframes\n","    frameinfo = (tb.tb_frame,) + getframeinfo(tb, context)\n","  File \"/usr/lib/python3.10/inspect.py\", line 1620, in getframeinfo\n","    filename = getsourcefile(frame) or getfile(frame)\n","  File \"/usr/lib/python3.10/inspect.py\", line 829, in getsourcefile\n","    module = getmodule(object, filename)\n","  File \"/usr/lib/python3.10/inspect.py\", line 861, in getmodule\n","    file = getabsfile(object, _filename)\n","  File \"/usr/lib/python3.10/inspect.py\", line 845, in getabsfile\n","    return os.path.normcase(os.path.abspath(_filename))\n","  File \"/usr/lib/python3.10/posixpath.py\", line 384, in abspath\n","    cwd = os.getcwd()\n","OSError: [Errno 107] Transport endpoint is not connected\n","Traceback (most recent call last):\n","  File \"/usr/local/lib/python3.10/dist-packages/IPython/core/interactiveshell.py\", line 3553, in run_code\n","    exec(code_obj, self.user_global_ns, self.user_ns)\n","  File \"\u003cipython-input-23-8dadbe3f0a94\u003e\", line 2, in \u003ccell line: 2\u003e\n","    image = io.imread('./facades/Ours_UIEB/0.jpg')\n","NameError: name 'io' is not defined\n","\n","During handling of the above exception, another exception occurred:\n","\n","Traceback (most recent call last):\n","  File \"/usr/local/lib/python3.10/dist-packages/IPython/core/interactiveshell.py\", line 2099, in showtraceback\n","    stb = value._render_traceback_()\n","AttributeError: 'NameError' object has no attribute '_render_traceback_'\n","\n","During handling of the above exception, another exception occurred:\n","\n","Traceback (most recent call last):\n","  File \"/usr/local/lib/python3.10/dist-packages/IPython/core/interactiveshell.py\", line 3473, in run_ast_nodes\n","    if (await self.run_code(code, result,  async_=asy)):\n","  File \"/usr/local/lib/python3.10/dist-packages/IPython/core/interactiveshell.py\", line 3575, in run_code\n","    self.showtraceback(running_compiled_code=True)\n","  File \"/usr/local/lib/python3.10/dist-packages/IPython/core/interactiveshell.py\", line 2101, in showtraceback\n","    stb = self.InteractiveTB.structured_traceback(etype,\n","  File \"/usr/local/lib/python3.10/dist-packages/IPython/core/ultratb.py\", line 1367, in structured_traceback\n","    return FormattedTB.structured_traceback(\n","  File \"/usr/local/lib/python3.10/dist-packages/IPython/core/ultratb.py\", line 1267, in structured_traceback\n","    return VerboseTB.structured_traceback(\n","  File \"/usr/local/lib/python3.10/dist-packages/IPython/core/ultratb.py\", line 1124, in structured_traceback\n","    formatted_exception = self.format_exception_as_a_whole(etype, evalue, etb, number_of_lines_of_context,\n","  File \"/usr/local/lib/python3.10/dist-packages/IPython/core/ultratb.py\", line 1082, in format_exception_as_a_whole\n","    last_unique, recursion_repeat = find_recursion(orig_etype, evalue, records)\n","  File \"/usr/local/lib/python3.10/dist-packages/IPython/core/ultratb.py\", line 382, in find_recursion\n","    return len(records), 0\n","TypeError: object of type 'NoneType' has no len()\n","\n","During handling of the above exception, another exception occurred:\n","\n","Traceback (most recent call last):\n","  File \"/usr/local/lib/python3.10/dist-packages/IPython/core/interactiveshell.py\", line 2099, in showtraceback\n","    stb = value._render_traceback_()\n","AttributeError: 'TypeError' object has no attribute '_render_traceback_'\n","\n","During handling of the above exception, another exception occurred:\n","\n","Traceback (most recent call last):\n","  File \"/usr/local/lib/python3.10/dist-packages/IPython/core/ultratb.py\", line 1101, in get_records\n","    return _fixed_getinnerframes(etb, number_of_lines_of_context, tb_offset)\n","  File \"/usr/local/lib/python3.10/dist-packages/IPython/core/ultratb.py\", line 248, in wrapped\n","    return f(*args, **kwargs)\n","  File \"/usr/local/lib/python3.10/dist-packages/IPython/core/ultratb.py\", line 281, in _fixed_getinnerframes\n","    records = fix_frame_records_filenames(inspect.getinnerframes(etb, context))\n","  File \"/usr/lib/python3.10/inspect.py\", line 1662, in getinnerframes\n","    frameinfo = (tb.tb_frame,) + getframeinfo(tb, context)\n","  File \"/usr/lib/python3.10/inspect.py\", line 1620, in getframeinfo\n","    filename = getsourcefile(frame) or getfile(frame)\n","  File \"/usr/lib/python3.10/inspect.py\", line 829, in getsourcefile\n","    module = getmodule(object, filename)\n","  File \"/usr/lib/python3.10/inspect.py\", line 861, in getmodule\n","    file = getabsfile(object, _filename)\n","  File \"/usr/lib/python3.10/inspect.py\", line 845, in getabsfile\n","    return os.path.normcase(os.path.abspath(_filename))\n","  File \"/usr/lib/python3.10/posixpath.py\", line 384, in abspath\n","    cwd = os.getcwd()\n","OSError: [Errno 107] Transport endpoint is not connected\n","Traceback (most recent call last):\n","  File \"/usr/local/lib/python3.10/dist-packages/IPython/core/interactiveshell.py\", line 3553, in run_code\n","    exec(code_obj, self.user_global_ns, self.user_ns)\n","  File \"\u003cipython-input-23-8dadbe3f0a94\u003e\", line 2, in \u003ccell line: 2\u003e\n","    image = io.imread('./facades/Ours_UIEB/0.jpg')\n","NameError: name 'io' is not defined\n","\n","During handling of the above exception, another exception occurred:\n","\n","Traceback (most recent call last):\n","  File \"/usr/local/lib/python3.10/dist-packages/IPython/core/interactiveshell.py\", line 2099, in showtraceback\n","    stb = value._render_traceback_()\n","AttributeError: 'NameError' object has no attribute '_render_traceback_'\n","\n","During handling of the above exception, another exception occurred:\n","\n","Traceback (most recent call last):\n","  File \"/usr/local/lib/python3.10/dist-packages/IPython/core/interactiveshell.py\", line 3473, in run_ast_nodes\n","    if (await self.run_code(code, result,  async_=asy)):\n","  File \"/usr/local/lib/python3.10/dist-packages/IPython/core/interactiveshell.py\", line 3575, in run_code\n","    self.showtraceback(running_compiled_code=True)\n","  File \"/usr/local/lib/python3.10/dist-packages/IPython/core/interactiveshell.py\", line 2101, in showtraceback\n","    stb = self.InteractiveTB.structured_traceback(etype,\n","  File \"/usr/local/lib/python3.10/dist-packages/IPython/core/ultratb.py\", line 1367, in structured_traceback\n","    return FormattedTB.structured_traceback(\n","  File \"/usr/local/lib/python3.10/dist-packages/IPython/core/ultratb.py\", line 1267, in structured_traceback\n","    return VerboseTB.structured_traceback(\n","  File \"/usr/local/lib/python3.10/dist-packages/IPython/core/ultratb.py\", line 1124, in structured_traceback\n","    formatted_exception = self.format_exception_as_a_whole(etype, evalue, etb, number_of_lines_of_context,\n","  File \"/usr/local/lib/python3.10/dist-packages/IPython/core/ultratb.py\", line 1082, in format_exception_as_a_whole\n","    last_unique, recursion_repeat = find_recursion(orig_etype, evalue, records)\n","  File \"/usr/local/lib/python3.10/dist-packages/IPython/core/ultratb.py\", line 382, in find_recursion\n","    return len(records), 0\n","TypeError: object of type 'NoneType' has no len()\n","\n","During handling of the above exception, another exception occurred:\n","\n","Traceback (most recent call last):\n","  File \"/usr/local/lib/python3.10/dist-packages/IPython/core/interactiveshell.py\", line 2099, in showtraceback\n","    stb = value._render_traceback_()\n","AttributeError: 'TypeError' object has no attribute '_render_traceback_'\n","\n","During handling of the above exception, another exception occurred:\n","\n","Traceback (most recent call last):\n","  File \"/usr/local/lib/python3.10/dist-packages/IPython/core/interactiveshell.py\", line 3030, in _run_cell\n","    return runner(coro)\n","  File \"/usr/local/lib/python3.10/dist-packages/IPython/core/async_helpers.py\", line 78, in _pseudo_sync_runner\n","    coro.send(None)\n","  File \"/usr/local/lib/python3.10/dist-packages/IPython/core/interactiveshell.py\", line 3257, in run_cell_async\n","    has_raised = await self.run_ast_nodes(code_ast.body, cell_name,\n","  File \"/usr/local/lib/python3.10/dist-packages/IPython/core/interactiveshell.py\", line 3492, in run_ast_nodes\n","    self.showtraceback()\n","  File \"/usr/local/lib/python3.10/dist-packages/IPython/core/interactiveshell.py\", line 2101, in showtraceback\n","    stb = self.InteractiveTB.structured_traceback(etype,\n","  File \"/usr/local/lib/python3.10/dist-packages/IPython/core/ultratb.py\", line 1367, in structured_traceback\n","    return FormattedTB.structured_traceback(\n","  File \"/usr/local/lib/python3.10/dist-packages/IPython/core/ultratb.py\", line 1267, in structured_traceback\n","    return VerboseTB.structured_traceback(\n","  File \"/usr/local/lib/python3.10/dist-packages/IPython/core/ultratb.py\", line 1142, in structured_traceback\n","    formatted_exceptions += self.format_exception_as_a_whole(etype, evalue, etb, lines_of_context,\n","  File \"/usr/local/lib/python3.10/dist-packages/IPython/core/ultratb.py\", line 1082, in format_exception_as_a_whole\n","    last_unique, recursion_repeat = find_recursion(orig_etype, evalue, records)\n","  File \"/usr/local/lib/python3.10/dist-packages/IPython/core/ultratb.py\", line 382, in find_recursion\n","    return len(records), 0\n","TypeError: object of type 'NoneType' has no len()\n","\n","During handling of the above exception, another exception occurred:\n","\n","Traceback (most recent call last):\n","  File \"/usr/local/lib/python3.10/dist-packages/IPython/core/interactiveshell.py\", line 2099, in showtraceback\n","    stb = value._render_traceback_()\n","AttributeError: 'TypeError' object has no attribute '_render_traceback_'\n","\n","During handling of the above exception, another exception occurred:\n","\n","Traceback (most recent call last):\n","  File \"/usr/local/lib/python3.10/dist-packages/IPython/core/ultratb.py\", line 1101, in get_records\n","    return _fixed_getinnerframes(etb, number_of_lines_of_context, tb_offset)\n","  File \"/usr/local/lib/python3.10/dist-packages/IPython/core/ultratb.py\", line 248, in wrapped\n","    return f(*args, **kwargs)\n","  File \"/usr/local/lib/python3.10/dist-packages/IPython/core/ultratb.py\", line 281, in _fixed_getinnerframes\n","    records = fix_frame_records_filenames(inspect.getinnerframes(etb, context))\n","  File \"/usr/lib/python3.10/inspect.py\", line 1662, in getinnerframes\n","    frameinfo = (tb.tb_frame,) + getframeinfo(tb, context)\n","  File \"/usr/lib/python3.10/inspect.py\", line 1620, in getframeinfo\n","    filename = getsourcefile(frame) or getfile(frame)\n","  File \"/usr/lib/python3.10/inspect.py\", line 829, in getsourcefile\n","    module = getmodule(object, filename)\n","  File \"/usr/lib/python3.10/inspect.py\", line 861, in getmodule\n","    file = getabsfile(object, _filename)\n","  File \"/usr/lib/python3.10/inspect.py\", line 845, in getabsfile\n","    return os.path.normcase(os.path.abspath(_filename))\n","  File \"/usr/lib/python3.10/posixpath.py\", line 384, in abspath\n","    cwd = os.getcwd()\n","OSError: [Errno 107] Transport endpoint is not connected\n"]}],"source":["# Now display the corresponding enhanced image\n","image = io.imread('./facades/Ours_UIEB/0.jpg')\n","image_2 = cv.cvtColor(image, cv.COLOR_BGR2RGB)\n","cv2_imshow(image_2)"]},{"cell_type":"code","execution_count":22,"metadata":{"executionInfo":{"elapsed":17,"status":"ok","timestamp":1715733816532,"user":{"displayName":"Adithyaa seran","userId":"15600754421888670023"},"user_tz":-330},"id":"svsrOkuEdK2w"},"outputs":[],"source":[]},{"cell_type":"code","execution_count":null,"metadata":{"colab":{"background_save":true,"base_uri":"https://localhost:8080/"},"id":"LCb7AMxrdIHX"},"outputs":[{"name":"stderr","output_type":"stream","text":["ERROR:root:Internal Python error in the inspect module.\n","Below is the traceback from this internal error.\n","\n","ERROR:root:Internal Python error in the inspect module.\n","Below is the traceback from this internal error.\n","\n","ERROR:root:Internal Python error in the inspect module.\n","Below is the traceback from this internal error.\n","\n"]},{"name":"stdout","output_type":"stream","text":["Traceback (most recent call last):\n","  File \"/usr/local/lib/python3.10/dist-packages/IPython/core/interactiveshell.py\", line 3553, in run_code\n","    exec(code_obj, self.user_global_ns, self.user_ns)\n","  File \"\u003cipython-input-23-3bdbf6df2832\u003e\", line 1, in \u003ccell line: 1\u003e\n","    get_ipython().run_line_magic('cd', '/content/drive/MyDrive/FYP_APRIL/Resolution_enhancer')\n","  File \"/usr/local/lib/python3.10/dist-packages/IPython/core/interactiveshell.py\", line 2418, in run_line_magic\n","    result = fn(*args, **kwargs)\n","  File \"\u003cdecorator-gen-85\u003e\", line 2, in cd\n","  File \"/usr/local/lib/python3.10/dist-packages/IPython/core/magic.py\", line 187, in \u003clambda\u003e\n","    call = lambda f, *a, **k: f(*a, **k)\n","  File \"/usr/local/lib/python3.10/dist-packages/IPython/core/magics/osm.py\", line 342, in cd\n","    oldcwd = os.getcwd()\n","OSError: [Errno 107] Transport endpoint is not connected\n","\n","During handling of the above exception, another exception occurred:\n","\n","Traceback (most recent call last):\n","  File \"/usr/local/lib/python3.10/dist-packages/IPython/core/interactiveshell.py\", line 2099, in showtraceback\n","    stb = value._render_traceback_()\n","AttributeError: 'OSError' object has no attribute '_render_traceback_'\n","\n","During handling of the above exception, another exception occurred:\n","\n","Traceback (most recent call last):\n","  File \"/usr/local/lib/python3.10/dist-packages/IPython/core/ultratb.py\", line 1101, in get_records\n","    return _fixed_getinnerframes(etb, number_of_lines_of_context, tb_offset)\n","  File \"/usr/local/lib/python3.10/dist-packages/IPython/core/ultratb.py\", line 248, in wrapped\n","    return f(*args, **kwargs)\n","  File \"/usr/local/lib/python3.10/dist-packages/IPython/core/ultratb.py\", line 281, in _fixed_getinnerframes\n","    records = fix_frame_records_filenames(inspect.getinnerframes(etb, context))\n","  File \"/usr/lib/python3.10/inspect.py\", line 1662, in getinnerframes\n","    frameinfo = (tb.tb_frame,) + getframeinfo(tb, context)\n","  File \"/usr/lib/python3.10/inspect.py\", line 1620, in getframeinfo\n","    filename = getsourcefile(frame) or getfile(frame)\n","  File \"/usr/lib/python3.10/inspect.py\", line 829, in getsourcefile\n","    module = getmodule(object, filename)\n","  File \"/usr/lib/python3.10/inspect.py\", line 861, in getmodule\n","    file = getabsfile(object, _filename)\n","  File \"/usr/lib/python3.10/inspect.py\", line 845, in getabsfile\n","    return os.path.normcase(os.path.abspath(_filename))\n","  File \"/usr/lib/python3.10/posixpath.py\", line 384, in abspath\n","    cwd = os.getcwd()\n","OSError: [Errno 107] Transport endpoint is not connected\n","Traceback (most recent call last):\n","  File \"/usr/local/lib/python3.10/dist-packages/IPython/core/interactiveshell.py\", line 3553, in run_code\n","    exec(code_obj, self.user_global_ns, self.user_ns)\n","  File \"\u003cipython-input-23-3bdbf6df2832\u003e\", line 1, in \u003ccell line: 1\u003e\n","    get_ipython().run_line_magic('cd', '/content/drive/MyDrive/FYP_APRIL/Resolution_enhancer')\n","  File \"/usr/local/lib/python3.10/dist-packages/IPython/core/interactiveshell.py\", line 2418, in run_line_magic\n","    result = fn(*args, **kwargs)\n","  File \"\u003cdecorator-gen-85\u003e\", line 2, in cd\n","  File \"/usr/local/lib/python3.10/dist-packages/IPython/core/magic.py\", line 187, in \u003clambda\u003e\n","    call = lambda f, *a, **k: f(*a, **k)\n","  File \"/usr/local/lib/python3.10/dist-packages/IPython/core/magics/osm.py\", line 342, in cd\n","    oldcwd = os.getcwd()\n","OSError: [Errno 107] Transport endpoint is not connected\n","\n","During handling of the above exception, another exception occurred:\n","\n","Traceback (most recent call last):\n","  File \"/usr/local/lib/python3.10/dist-packages/IPython/core/interactiveshell.py\", line 2099, in showtraceback\n","    stb = value._render_traceback_()\n","AttributeError: 'OSError' object has no attribute '_render_traceback_'\n","\n","During handling of the above exception, another exception occurred:\n","\n","Traceback (most recent call last):\n","  File \"/usr/local/lib/python3.10/dist-packages/IPython/core/interactiveshell.py\", line 3473, in run_ast_nodes\n","    if (await self.run_code(code, result,  async_=asy)):\n","  File \"/usr/local/lib/python3.10/dist-packages/IPython/core/interactiveshell.py\", line 3575, in run_code\n","    self.showtraceback(running_compiled_code=True)\n","  File \"/usr/local/lib/python3.10/dist-packages/IPython/core/interactiveshell.py\", line 2101, in showtraceback\n","    stb = self.InteractiveTB.structured_traceback(etype,\n","  File \"/usr/local/lib/python3.10/dist-packages/IPython/core/ultratb.py\", line 1367, in structured_traceback\n","    return FormattedTB.structured_traceback(\n","  File \"/usr/local/lib/python3.10/dist-packages/IPython/core/ultratb.py\", line 1267, in structured_traceback\n","    return VerboseTB.structured_traceback(\n","  File \"/usr/local/lib/python3.10/dist-packages/IPython/core/ultratb.py\", line 1124, in structured_traceback\n","    formatted_exception = self.format_exception_as_a_whole(etype, evalue, etb, number_of_lines_of_context,\n","  File \"/usr/local/lib/python3.10/dist-packages/IPython/core/ultratb.py\", line 1082, in format_exception_as_a_whole\n","    last_unique, recursion_repeat = find_recursion(orig_etype, evalue, records)\n","  File \"/usr/local/lib/python3.10/dist-packages/IPython/core/ultratb.py\", line 382, in find_recursion\n","    return len(records), 0\n","TypeError: object of type 'NoneType' has no len()\n","\n","During handling of the above exception, another exception occurred:\n","\n","Traceback (most recent call last):\n","  File \"/usr/local/lib/python3.10/dist-packages/IPython/core/interactiveshell.py\", line 2099, in showtraceback\n","    stb = value._render_traceback_()\n","AttributeError: 'TypeError' object has no attribute '_render_traceback_'\n","\n","During handling of the above exception, another exception occurred:\n","\n","Traceback (most recent call last):\n","  File \"/usr/local/lib/python3.10/dist-packages/IPython/core/ultratb.py\", line 1101, in get_records\n","    return _fixed_getinnerframes(etb, number_of_lines_of_context, tb_offset)\n","  File \"/usr/local/lib/python3.10/dist-packages/IPython/core/ultratb.py\", line 248, in wrapped\n","    return f(*args, **kwargs)\n","  File \"/usr/local/lib/python3.10/dist-packages/IPython/core/ultratb.py\", line 281, in _fixed_getinnerframes\n","    records = fix_frame_records_filenames(inspect.getinnerframes(etb, context))\n","  File \"/usr/lib/python3.10/inspect.py\", line 1662, in getinnerframes\n","    frameinfo = (tb.tb_frame,) + getframeinfo(tb, context)\n","  File \"/usr/lib/python3.10/inspect.py\", line 1620, in getframeinfo\n","    filename = getsourcefile(frame) or getfile(frame)\n","  File \"/usr/lib/python3.10/inspect.py\", line 829, in getsourcefile\n","    module = getmodule(object, filename)\n","  File \"/usr/lib/python3.10/inspect.py\", line 861, in getmodule\n","    file = getabsfile(object, _filename)\n","  File \"/usr/lib/python3.10/inspect.py\", line 845, in getabsfile\n","    return os.path.normcase(os.path.abspath(_filename))\n","  File \"/usr/lib/python3.10/posixpath.py\", line 384, in abspath\n","    cwd = os.getcwd()\n","OSError: [Errno 107] Transport endpoint is not connected\n","Traceback (most recent call last):\n","  File \"/usr/local/lib/python3.10/dist-packages/IPython/core/interactiveshell.py\", line 3553, in run_code\n","    exec(code_obj, self.user_global_ns, self.user_ns)\n","  File \"\u003cipython-input-23-3bdbf6df2832\u003e\", line 1, in \u003ccell line: 1\u003e\n","    get_ipython().run_line_magic('cd', '/content/drive/MyDrive/FYP_APRIL/Resolution_enhancer')\n","  File \"/usr/local/lib/python3.10/dist-packages/IPython/core/interactiveshell.py\", line 2418, in run_line_magic\n","    result = fn(*args, **kwargs)\n","  File \"\u003cdecorator-gen-85\u003e\", line 2, in cd\n","  File \"/usr/local/lib/python3.10/dist-packages/IPython/core/magic.py\", line 187, in \u003clambda\u003e\n","    call = lambda f, *a, **k: f(*a, **k)\n","  File \"/usr/local/lib/python3.10/dist-packages/IPython/core/magics/osm.py\", line 342, in cd\n","    oldcwd = os.getcwd()\n","OSError: [Errno 107] Transport endpoint is not connected\n","\n","During handling of the above exception, another exception occurred:\n","\n","Traceback (most recent call last):\n","  File \"/usr/local/lib/python3.10/dist-packages/IPython/core/interactiveshell.py\", line 2099, in showtraceback\n","    stb = value._render_traceback_()\n","AttributeError: 'OSError' object has no attribute '_render_traceback_'\n","\n","During handling of the above exception, another exception occurred:\n","\n","Traceback (most recent call last):\n","  File \"/usr/local/lib/python3.10/dist-packages/IPython/core/interactiveshell.py\", line 3473, in run_ast_nodes\n","    if (await self.run_code(code, result,  async_=asy)):\n","  File \"/usr/local/lib/python3.10/dist-packages/IPython/core/interactiveshell.py\", line 3575, in run_code\n","    self.showtraceback(running_compiled_code=True)\n","  File \"/usr/local/lib/python3.10/dist-packages/IPython/core/interactiveshell.py\", line 2101, in showtraceback\n","    stb = self.InteractiveTB.structured_traceback(etype,\n","  File \"/usr/local/lib/python3.10/dist-packages/IPython/core/ultratb.py\", line 1367, in structured_traceback\n","    return FormattedTB.structured_traceback(\n","  File \"/usr/local/lib/python3.10/dist-packages/IPython/core/ultratb.py\", line 1267, in structured_traceback\n","    return VerboseTB.structured_traceback(\n","  File \"/usr/local/lib/python3.10/dist-packages/IPython/core/ultratb.py\", line 1124, in structured_traceback\n","    formatted_exception = self.format_exception_as_a_whole(etype, evalue, etb, number_of_lines_of_context,\n","  File \"/usr/local/lib/python3.10/dist-packages/IPython/core/ultratb.py\", line 1082, in format_exception_as_a_whole\n","    last_unique, recursion_repeat = find_recursion(orig_etype, evalue, records)\n","  File \"/usr/local/lib/python3.10/dist-packages/IPython/core/ultratb.py\", line 382, in find_recursion\n","    return len(records), 0\n","TypeError: object of type 'NoneType' has no len()\n","\n","During handling of the above exception, another exception occurred:\n","\n","Traceback (most recent call last):\n","  File \"/usr/local/lib/python3.10/dist-packages/IPython/core/interactiveshell.py\", line 2099, in showtraceback\n","    stb = value._render_traceback_()\n","AttributeError: 'TypeError' object has no attribute '_render_traceback_'\n","\n","During handling of the above exception, another exception occurred:\n","\n","Traceback (most recent call last):\n","  File \"/usr/local/lib/python3.10/dist-packages/IPython/core/interactiveshell.py\", line 3030, in _run_cell\n","    return runner(coro)\n","  File \"/usr/local/lib/python3.10/dist-packages/IPython/core/async_helpers.py\", line 78, in _pseudo_sync_runner\n","    coro.send(None)\n","  File \"/usr/local/lib/python3.10/dist-packages/IPython/core/interactiveshell.py\", line 3257, in run_cell_async\n","    has_raised = await self.run_ast_nodes(code_ast.body, cell_name,\n","  File \"/usr/local/lib/python3.10/dist-packages/IPython/core/interactiveshell.py\", line 3492, in run_ast_nodes\n","    self.showtraceback()\n","  File \"/usr/local/lib/python3.10/dist-packages/IPython/core/interactiveshell.py\", line 2101, in showtraceback\n","    stb = self.InteractiveTB.structured_traceback(etype,\n","  File \"/usr/local/lib/python3.10/dist-packages/IPython/core/ultratb.py\", line 1367, in structured_traceback\n","    return FormattedTB.structured_traceback(\n","  File \"/usr/local/lib/python3.10/dist-packages/IPython/core/ultratb.py\", line 1267, in structured_traceback\n","    return VerboseTB.structured_traceback(\n","  File \"/usr/local/lib/python3.10/dist-packages/IPython/core/ultratb.py\", line 1142, in structured_traceback\n","    formatted_exceptions += self.format_exception_as_a_whole(etype, evalue, etb, lines_of_context,\n","  File \"/usr/local/lib/python3.10/dist-packages/IPython/core/ultratb.py\", line 1082, in format_exception_as_a_whole\n","    last_unique, recursion_repeat = find_recursion(orig_etype, evalue, records)\n","  File \"/usr/local/lib/python3.10/dist-packages/IPython/core/ultratb.py\", line 382, in find_recursion\n","    return len(records), 0\n","TypeError: object of type 'NoneType' has no len()\n","\n","During handling of the above exception, another exception occurred:\n","\n","Traceback (most recent call last):\n","  File \"/usr/local/lib/python3.10/dist-packages/IPython/core/interactiveshell.py\", line 2099, in showtraceback\n","    stb = value._render_traceback_()\n","AttributeError: 'TypeError' object has no attribute '_render_traceback_'\n","\n","During handling of the above exception, another exception occurred:\n","\n","Traceback (most recent call last):\n","  File \"/usr/local/lib/python3.10/dist-packages/IPython/core/ultratb.py\", line 1101, in get_records\n","    return _fixed_getinnerframes(etb, number_of_lines_of_context, tb_offset)\n","  File \"/usr/local/lib/python3.10/dist-packages/IPython/core/ultratb.py\", line 248, in wrapped\n","    return f(*args, **kwargs)\n","  File \"/usr/local/lib/python3.10/dist-packages/IPython/core/ultratb.py\", line 281, in _fixed_getinnerframes\n","    records = fix_frame_records_filenames(inspect.getinnerframes(etb, context))\n","  File \"/usr/lib/python3.10/inspect.py\", line 1662, in getinnerframes\n","    frameinfo = (tb.tb_frame,) + getframeinfo(tb, context)\n","  File \"/usr/lib/python3.10/inspect.py\", line 1620, in getframeinfo\n","    filename = getsourcefile(frame) or getfile(frame)\n","  File \"/usr/lib/python3.10/inspect.py\", line 829, in getsourcefile\n","    module = getmodule(object, filename)\n","  File \"/usr/lib/python3.10/inspect.py\", line 861, in getmodule\n","    file = getabsfile(object, _filename)\n","  File \"/usr/lib/python3.10/inspect.py\", line 845, in getabsfile\n","    return os.path.normcase(os.path.abspath(_filename))\n","  File \"/usr/lib/python3.10/posixpath.py\", line 384, in abspath\n","    cwd = os.getcwd()\n","OSError: [Errno 107] Transport endpoint is not connected\n"]}],"source":["%cd /content/drive/MyDrive/FYP_APRIL/Resolution_enhancer\n","!pip install -r requirements.txt"]},{"cell_type":"code","execution_count":null,"metadata":{"colab":{"background_save":true,"base_uri":"https://localhost:8080/"},"id":"y6EvxDKydODL"},"outputs":[{"name":"stderr","output_type":"stream","text":["ERROR:root:Internal Python error in the inspect module.\n","Below is the traceback from this internal error.\n","\n"]},{"name":"stdout","output_type":"stream","text":["Traceback (most recent call last):\n","  File \"/usr/local/lib/python3.10/dist-packages/IPython/core/interactiveshell.py\", line 3553, in run_code\n","    exec(code_obj, self.user_global_ns, self.user_ns)\n","  File \"\u003cipython-input-23-58ba9b2a14b4\u003e\", line 18, in \u003ccell line: 18\u003e\n","    os.mkdir(result_folder)\n","OSError: [Errno 107] Transport endpoint is not connected: 'exps/quickstart_Enh/test_results'\n","\n","During handling of the above exception, another exception occurred:\n","\n","Traceback (most recent call last):\n","  File \"/usr/local/lib/python3.10/dist-packages/IPython/core/interactiveshell.py\", line 2099, in showtraceback\n","    stb = value._render_traceback_()\n","AttributeError: 'OSError' object has no attribute '_render_traceback_'\n","\n","During handling of the above exception, another exception occurred:\n","\n","Traceback (most recent call last):\n","  File \"/usr/local/lib/python3.10/dist-packages/IPython/core/ultratb.py\", line 1101, in get_records\n","    return _fixed_getinnerframes(etb, number_of_lines_of_context, tb_offset)\n","  File \"/usr/local/lib/python3.10/dist-packages/IPython/core/ultratb.py\", line 248, in wrapped\n","    return f(*args, **kwargs)\n","  File \"/usr/local/lib/python3.10/dist-packages/IPython/core/ultratb.py\", line 281, in _fixed_getinnerframes\n","    records = fix_frame_records_filenames(inspect.getinnerframes(etb, context))\n","  File \"/usr/lib/python3.10/inspect.py\", line 1662, in getinnerframes\n","    frameinfo = (tb.tb_frame,) + getframeinfo(tb, context)\n","  File \"/usr/lib/python3.10/inspect.py\", line 1620, in getframeinfo\n","    filename = getsourcefile(frame) or getfile(frame)\n","  File \"/usr/lib/python3.10/inspect.py\", line 829, in getsourcefile\n","    module = getmodule(object, filename)\n","  File \"/usr/lib/python3.10/inspect.py\", line 861, in getmodule\n","    file = getabsfile(object, _filename)\n","  File \"/usr/lib/python3.10/inspect.py\", line 845, in getabsfile\n","    return os.path.normcase(os.path.abspath(_filename))\n","  File \"/usr/lib/python3.10/posixpath.py\", line 384, in abspath\n","    cwd = os.getcwd()\n","OSError: [Errno 107] Transport endpoint is not connected\n"]},{"name":"stderr","output_type":"stream","text":["ERROR:root:Internal Python error in the inspect module.\n","Below is the traceback from this internal error.\n","\n"]},{"name":"stdout","output_type":"stream","text":["Traceback (most recent call last):\n","  File \"/usr/local/lib/python3.10/dist-packages/IPython/core/interactiveshell.py\", line 3553, in run_code\n","    exec(code_obj, self.user_global_ns, self.user_ns)\n","  File \"\u003cipython-input-23-58ba9b2a14b4\u003e\", line 18, in \u003ccell line: 18\u003e\n","    os.mkdir(result_folder)\n","OSError: [Errno 107] Transport endpoint is not connected: 'exps/quickstart_Enh/test_results'\n","\n","During handling of the above exception, another exception occurred:\n","\n","Traceback (most recent call last):\n","  File \"/usr/local/lib/python3.10/dist-packages/IPython/core/interactiveshell.py\", line 2099, in showtraceback\n","    stb = value._render_traceback_()\n","AttributeError: 'OSError' object has no attribute '_render_traceback_'\n","\n","During handling of the above exception, another exception occurred:\n","\n","Traceback (most recent call last):\n","  File \"/usr/local/lib/python3.10/dist-packages/IPython/core/interactiveshell.py\", line 3473, in run_ast_nodes\n","    if (await self.run_code(code, result,  async_=asy)):\n","  File \"/usr/local/lib/python3.10/dist-packages/IPython/core/interactiveshell.py\", line 3575, in run_code\n","    self.showtraceback(running_compiled_code=True)\n","  File \"/usr/local/lib/python3.10/dist-packages/IPython/core/interactiveshell.py\", line 2101, in showtraceback\n","    stb = self.InteractiveTB.structured_traceback(etype,\n","  File \"/usr/local/lib/python3.10/dist-packages/IPython/core/ultratb.py\", line 1367, in structured_traceback\n","    return FormattedTB.structured_traceback(\n","  File \"/usr/local/lib/python3.10/dist-packages/IPython/core/ultratb.py\", line 1267, in structured_traceback\n","    return VerboseTB.structured_traceback(\n","  File \"/usr/local/lib/python3.10/dist-packages/IPython/core/ultratb.py\", line 1124, in structured_traceback\n","    formatted_exception = self.format_exception_as_a_whole(etype, evalue, etb, number_of_lines_of_context,\n","  File \"/usr/local/lib/python3.10/dist-packages/IPython/core/ultratb.py\", line 1082, in format_exception_as_a_whole\n","    last_unique, recursion_repeat = find_recursion(orig_etype, evalue, records)\n","  File \"/usr/local/lib/python3.10/dist-packages/IPython/core/ultratb.py\", line 382, in find_recursion\n","    return len(records), 0\n","TypeError: object of type 'NoneType' has no len()\n","\n","During handling of the above exception, another exception occurred:\n","\n","Traceback (most recent call last):\n","  File \"/usr/local/lib/python3.10/dist-packages/IPython/core/interactiveshell.py\", line 2099, in showtraceback\n","    stb = value._render_traceback_()\n","AttributeError: 'TypeError' object has no attribute '_render_traceback_'\n","\n","During handling of the above exception, another exception occurred:\n","\n","Traceback (most recent call last):\n","  File \"/usr/local/lib/python3.10/dist-packages/IPython/core/ultratb.py\", line 1101, in get_records\n","    return _fixed_getinnerframes(etb, number_of_lines_of_context, tb_offset)\n","  File \"/usr/local/lib/python3.10/dist-packages/IPython/core/ultratb.py\", line 248, in wrapped\n","    return f(*args, **kwargs)\n","  File \"/usr/local/lib/python3.10/dist-packages/IPython/core/ultratb.py\", line 281, in _fixed_getinnerframes\n","    records = fix_frame_records_filenames(inspect.getinnerframes(etb, context))\n","  File \"/usr/lib/python3.10/inspect.py\", line 1662, in getinnerframes\n","    frameinfo = (tb.tb_frame,) + getframeinfo(tb, context)\n","  File \"/usr/lib/python3.10/inspect.py\", line 1620, in getframeinfo\n","    filename = getsourcefile(frame) or getfile(frame)\n","  File \"/usr/lib/python3.10/inspect.py\", line 829, in getsourcefile\n","    module = getmodule(object, filename)\n","  File \"/usr/lib/python3.10/inspect.py\", line 861, in getmodule\n","    file = getabsfile(object, _filename)\n","  File \"/usr/lib/python3.10/inspect.py\", line 845, in getabsfile\n","    return os.path.normcase(os.path.abspath(_filename))\n","  File \"/usr/lib/python3.10/posixpath.py\", line 384, in abspath\n","    cwd = os.getcwd()\n","OSError: [Errno 107] Transport endpoint is not connected\n"]},{"name":"stderr","output_type":"stream","text":["ERROR:root:Internal Python error in the inspect module.\n","Below is the traceback from this internal error.\n","\n"]},{"name":"stdout","output_type":"stream","text":["Traceback (most recent call last):\n","  File \"/usr/local/lib/python3.10/dist-packages/IPython/core/interactiveshell.py\", line 3553, in run_code\n","    exec(code_obj, self.user_global_ns, self.user_ns)\n","  File \"\u003cipython-input-23-58ba9b2a14b4\u003e\", line 18, in \u003ccell line: 18\u003e\n","    os.mkdir(result_folder)\n","OSError: [Errno 107] Transport endpoint is not connected: 'exps/quickstart_Enh/test_results'\n","\n","During handling of the above exception, another exception occurred:\n","\n","Traceback (most recent call last):\n","  File \"/usr/local/lib/python3.10/dist-packages/IPython/core/interactiveshell.py\", line 2099, in showtraceback\n","    stb = value._render_traceback_()\n","AttributeError: 'OSError' object has no attribute '_render_traceback_'\n","\n","During handling of the above exception, another exception occurred:\n","\n","Traceback (most recent call last):\n","  File \"/usr/local/lib/python3.10/dist-packages/IPython/core/interactiveshell.py\", line 3473, in run_ast_nodes\n","    if (await self.run_code(code, result,  async_=asy)):\n","  File \"/usr/local/lib/python3.10/dist-packages/IPython/core/interactiveshell.py\", line 3575, in run_code\n","    self.showtraceback(running_compiled_code=True)\n","  File \"/usr/local/lib/python3.10/dist-packages/IPython/core/interactiveshell.py\", line 2101, in showtraceback\n","    stb = self.InteractiveTB.structured_traceback(etype,\n","  File \"/usr/local/lib/python3.10/dist-packages/IPython/core/ultratb.py\", line 1367, in structured_traceback\n","    return FormattedTB.structured_traceback(\n","  File \"/usr/local/lib/python3.10/dist-packages/IPython/core/ultratb.py\", line 1267, in structured_traceback\n","    return VerboseTB.structured_traceback(\n","  File \"/usr/local/lib/python3.10/dist-packages/IPython/core/ultratb.py\", line 1124, in structured_traceback\n","    formatted_exception = self.format_exception_as_a_whole(etype, evalue, etb, number_of_lines_of_context,\n","  File \"/usr/local/lib/python3.10/dist-packages/IPython/core/ultratb.py\", line 1082, in format_exception_as_a_whole\n","    last_unique, recursion_repeat = find_recursion(orig_etype, evalue, records)\n","  File \"/usr/local/lib/python3.10/dist-packages/IPython/core/ultratb.py\", line 382, in find_recursion\n","    return len(records), 0\n","TypeError: object of type 'NoneType' has no len()\n","\n","During handling of the above exception, another exception occurred:\n","\n","Traceback (most recent call last):\n","  File \"/usr/local/lib/python3.10/dist-packages/IPython/core/interactiveshell.py\", line 2099, in showtraceback\n","    stb = value._render_traceback_()\n","AttributeError: 'TypeError' object has no attribute '_render_traceback_'\n","\n","During handling of the above exception, another exception occurred:\n","\n","Traceback (most recent call last):\n","  File \"/usr/local/lib/python3.10/dist-packages/IPython/core/interactiveshell.py\", line 3030, in _run_cell\n","    return runner(coro)\n","  File \"/usr/local/lib/python3.10/dist-packages/IPython/core/async_helpers.py\", line 78, in _pseudo_sync_runner\n","    coro.send(None)\n","  File \"/usr/local/lib/python3.10/dist-packages/IPython/core/interactiveshell.py\", line 3257, in run_cell_async\n","    has_raised = await self.run_ast_nodes(code_ast.body, cell_name,\n","  File \"/usr/local/lib/python3.10/dist-packages/IPython/core/interactiveshell.py\", line 3492, in run_ast_nodes\n","    self.showtraceback()\n","  File \"/usr/local/lib/python3.10/dist-packages/IPython/core/interactiveshell.py\", line 2101, in showtraceback\n","    stb = self.InteractiveTB.structured_traceback(etype,\n","  File \"/usr/local/lib/python3.10/dist-packages/IPython/core/ultratb.py\", line 1367, in structured_traceback\n","    return FormattedTB.structured_traceback(\n","  File \"/usr/local/lib/python3.10/dist-packages/IPython/core/ultratb.py\", line 1267, in structured_traceback\n","    return VerboseTB.structured_traceback(\n","  File \"/usr/local/lib/python3.10/dist-packages/IPython/core/ultratb.py\", line 1142, in structured_traceback\n","    formatted_exceptions += self.format_exception_as_a_whole(etype, evalue, etb, lines_of_context,\n","  File \"/usr/local/lib/python3.10/dist-packages/IPython/core/ultratb.py\", line 1082, in format_exception_as_a_whole\n","    last_unique, recursion_repeat = find_recursion(orig_etype, evalue, records)\n","  File \"/usr/local/lib/python3.10/dist-packages/IPython/core/ultratb.py\", line 382, in find_recursion\n","    return len(records), 0\n","TypeError: object of type 'NoneType' has no len()\n","\n","During handling of the above exception, another exception occurred:\n","\n","Traceback (most recent call last):\n","  File \"/usr/local/lib/python3.10/dist-packages/IPython/core/interactiveshell.py\", line 2099, in showtraceback\n","    stb = value._render_traceback_()\n","AttributeError: 'TypeError' object has no attribute '_render_traceback_'\n","\n","During handling of the above exception, another exception occurred:\n","\n","Traceback (most recent call last):\n","  File \"/usr/local/lib/python3.10/dist-packages/IPython/core/ultratb.py\", line 1101, in get_records\n","    return _fixed_getinnerframes(etb, number_of_lines_of_context, tb_offset)\n","  File \"/usr/local/lib/python3.10/dist-packages/IPython/core/ultratb.py\", line 248, in wrapped\n","    return f(*args, **kwargs)\n","  File \"/usr/local/lib/python3.10/dist-packages/IPython/core/ultratb.py\", line 281, in _fixed_getinnerframes\n","    records = fix_frame_records_filenames(inspect.getinnerframes(etb, context))\n","  File \"/usr/lib/python3.10/inspect.py\", line 1662, in getinnerframes\n","    frameinfo = (tb.tb_frame,) + getframeinfo(tb, context)\n","  File \"/usr/lib/python3.10/inspect.py\", line 1620, in getframeinfo\n","    filename = getsourcefile(frame) or getfile(frame)\n","  File \"/usr/lib/python3.10/inspect.py\", line 829, in getsourcefile\n","    module = getmodule(object, filename)\n","  File \"/usr/lib/python3.10/inspect.py\", line 861, in getmodule\n","    file = getabsfile(object, _filename)\n","  File \"/usr/lib/python3.10/inspect.py\", line 845, in getabsfile\n","    return os.path.normcase(os.path.abspath(_filename))\n","  File \"/usr/lib/python3.10/posixpath.py\", line 384, in abspath\n","    cwd = os.getcwd()\n","OSError: [Errno 107] Transport endpoint is not connected\n"]}],"source":["import os\n","import glob\n","from google.colab import files\n","import shutil\n","\n","# # to be compatible with BSRGAN\n","\n","# # !rm -r dataset/demo_data_Enh/test_data/input\n","# # !rm -r dataset/demo_data_Enh/test_data/target\n","# upload_folder = 'dataset/demo_data_Enh/test_data/input'\n","result_folder = 'exps/quickstart_Enh/test_results'\n","\n","# if os.path.isdir(upload_folder):\n","#     shutil.rmtree(upload_folder)\n","if os.path.isdir(result_folder):\n","    shutil.rmtree(result_folder)\n","# os.mkdir(upload_folder)\n","os.mkdir(result_folder)\n","\n","# # upload images\n","# uploaded = files.upload()\n","# for filename in uploaded.keys():\n","#   dst_path = os.path.join(upload_folder, filename)\n","#   print(f'move {filename} to {dst_path}')\n","#   shutil.move(filename, dst_path)\n","\n","import os\n","import shutil\n","\n","# Define the source and destination folders\n","src_folder = '/content/drive/MyDrive/FYP_APRIL/Colour_correction/facades/Ours_UIEB'\n","upload_folder = 'dataset/demo_data_Enh/test_data/input'\n","\n","# Create the destination folder if it doesn't exist\n","if not os.path.exists(upload_folder):\n","    os.makedirs(upload_folder)\n","\n","# Iterate over files in the source folder and copy them to the destination folder\n","for filename in os.listdir(src_folder):\n","    src_path = os.path.join(src_folder, filename)\n","    dst_path = os.path.join(upload_folder, filename)\n","    shutil.copy(src_path, dst_path)\n","    print(f'Moved {src_path} to {dst_path}')\n"]},{"cell_type":"code","execution_count":null,"metadata":{"colab":{"background_save":true,"base_uri":"https://localhost:8080/"},"id":"U5afvZ40dQDr"},"outputs":[{"name":"stderr","output_type":"stream","text":["ERROR:root:Internal Python error in the inspect module.\n","Below is the traceback from this internal error.\n","\n"]},{"name":"stdout","output_type":"stream","text":["Traceback (most recent call last):\n","  File \"/usr/local/lib/python3.10/dist-packages/IPython/core/interactiveshell.py\", line 3553, in run_code\n","    exec(code_obj, self.user_global_ns, self.user_ns)\n","  File \"\u003cipython-input-23-f36854496bb4\u003e\", line 2, in \u003ccell line: 2\u003e\n","    get_ipython().run_line_magic('cd', 'scripts')\n","  File \"/usr/local/lib/python3.10/dist-packages/IPython/core/interactiveshell.py\", line 2418, in run_line_magic\n","    result = fn(*args, **kwargs)\n","  File \"\u003cdecorator-gen-85\u003e\", line 2, in cd\n","  File \"/usr/local/lib/python3.10/dist-packages/IPython/core/magic.py\", line 187, in \u003clambda\u003e\n","    call = lambda f, *a, **k: f(*a, **k)\n","  File \"/usr/local/lib/python3.10/dist-packages/IPython/core/magics/osm.py\", line 342, in cd\n","    oldcwd = os.getcwd()\n","OSError: [Errno 107] Transport endpoint is not connected\n","\n","During handling of the above exception, another exception occurred:\n","\n","Traceback (most recent call last):\n","  File \"/usr/local/lib/python3.10/dist-packages/IPython/core/interactiveshell.py\", line 2099, in showtraceback\n","    stb = value._render_traceback_()\n","AttributeError: 'OSError' object has no attribute '_render_traceback_'\n","\n","During handling of the above exception, another exception occurred:\n","\n","Traceback (most recent call last):\n","  File \"/usr/local/lib/python3.10/dist-packages/IPython/core/ultratb.py\", line 1101, in get_records\n","    return _fixed_getinnerframes(etb, number_of_lines_of_context, tb_offset)\n"]},{"name":"stderr","output_type":"stream","text":["ERROR:root:Internal Python error in the inspect module.\n","Below is the traceback from this internal error.\n","\n"]},{"name":"stdout","output_type":"stream","text":["  File \"/usr/local/lib/python3.10/dist-packages/IPython/core/ultratb.py\", line 248, in wrapped\n","    return f(*args, **kwargs)\n","  File \"/usr/local/lib/python3.10/dist-packages/IPython/core/ultratb.py\", line 281, in _fixed_getinnerframes\n","    records = fix_frame_records_filenames(inspect.getinnerframes(etb, context))\n","  File \"/usr/lib/python3.10/inspect.py\", line 1662, in getinnerframes\n","    frameinfo = (tb.tb_frame,) + getframeinfo(tb, context)\n","  File \"/usr/lib/python3.10/inspect.py\", line 1620, in getframeinfo\n","    filename = getsourcefile(frame) or getfile(frame)\n","  File \"/usr/lib/python3.10/inspect.py\", line 829, in getsourcefile\n","    module = getmodule(object, filename)\n","  File \"/usr/lib/python3.10/inspect.py\", line 861, in getmodule\n","    file = getabsfile(object, _filename)\n","  File \"/usr/lib/python3.10/inspect.py\", line 845, in getabsfile\n","    return os.path.normcase(os.path.abspath(_filename))\n","  File \"/usr/lib/python3.10/posixpath.py\", line 384, in abspath\n","    cwd = os.getcwd()\n","OSError: [Errno 107] Transport endpoint is not connected\n","Traceback (most recent call last):\n","  File \"/usr/local/lib/python3.10/dist-packages/IPython/core/interactiveshell.py\", line 3553, in run_code\n","    exec(code_obj, self.user_global_ns, self.user_ns)\n","  File \"\u003cipython-input-23-f36854496bb4\u003e\", line 2, in \u003ccell line: 2\u003e\n","    get_ipython().run_line_magic('cd', 'scripts')\n","  File \"/usr/local/lib/python3.10/dist-packages/IPython/core/interactiveshell.py\", line 2418, in run_line_magic\n","    result = fn(*args, **kwargs)\n","  File \"\u003cdecorator-gen-85\u003e\", line 2, in cd\n","  File \"/usr/local/lib/python3.10/dist-packages/IPython/core/magic.py\", line 187, in \u003clambda\u003e\n","    call = lambda f, *a, **k: f(*a, **k)\n","  File \"/usr/local/lib/python3.10/dist-packages/IPython/core/magics/osm.py\", line 342, in cd\n","    oldcwd = os.getcwd()\n","OSError: [Errno 107] Transport endpoint is not connected\n","\n","During handling of the above exception, another exception occurred:\n","\n","Traceback (most recent call last):\n","  File \"/usr/local/lib/python3.10/dist-packages/IPython/core/interactiveshell.py\", line 2099, in showtraceback\n","    stb = value._render_traceback_()\n","AttributeError: 'OSError' object has no attribute '_render_traceback_'\n","\n","During handling of the above exception, another exception occurred:\n","\n","Traceback (most recent call last):\n","  File \"/usr/local/lib/python3.10/dist-packages/IPython/core/interactiveshell.py\", line 3473, in run_ast_nodes\n","    if (await self.run_code(code, result,  async_=asy)):\n","  File \"/usr/local/lib/python3.10/dist-packages/IPython/core/interactiveshell.py\", line 3575, in run_code\n","    self.showtraceback(running_compiled_code=True)\n","  File \"/usr/local/lib/python3.10/dist-packages/IPython/core/interactiveshell.py\", line 2101, in showtraceback\n","    stb = self.InteractiveTB.structured_traceback(etype,\n","  File \"/usr/local/lib/python3.10/dist-packages/IPython/core/ultratb.py\", line 1367, in structured_traceback\n","    return FormattedTB.structured_traceback(\n","  File \"/usr/local/lib/python3.10/dist-packages/IPython/core/ultratb.py\", line 1267, in structured_traceback\n","    return VerboseTB.structured_traceback(\n","  File \"/usr/local/lib/python3.10/dist-packages/IPython/core/ultratb.py\", line 1124, in structured_traceback\n","    formatted_exception = self.format_exception_as_a_whole(etype, evalue, etb, number_of_lines_of_context,\n","  File \"/usr/local/lib/python3.10/dist-packages/IPython/core/ultratb.py\", line 1082, in format_exception_as_a_whole\n","    last_unique, recursion_repeat = find_recursion(orig_etype, evalue, records)\n","  File \"/usr/local/lib/python3.10/dist-packages/IPython/core/ultratb.py\", line 382, in find_recursion\n","    return len(records), 0\n","TypeError: object of type 'NoneType' has no len()\n","\n","During handling of the above exception, another exception occurred:\n","\n","Traceback (most recent call last):\n","  File \"/usr/local/lib/python3.10/dist-packages/IPython/core/interactiveshell.py\", line 2099, in showtraceback\n","    stb = value._render_traceback_()\n","AttributeError: 'TypeError' object has no attribute '_render_traceback_'\n","\n","During handling of the above exception, another exception occurred:\n","\n","Traceback (most recent call last):\n","  File \"/usr/local/lib/python3.10/dist-packages/IPython/core/ultratb.py\", line 1101, in get_records\n","    return _fixed_getinnerframes(etb, number_of_lines_of_context, tb_offset)\n","  File \"/usr/local/lib/python3.10/dist-packages/IPython/core/ultratb.py\", line 248, in wrapped\n","    return f(*args, **kwargs)\n","  File \"/usr/local/lib/python3.10/dist-packages/IPython/core/ultratb.py\", line 281, in _fixed_getinnerframes\n","    records = fix_frame_records_filenames(inspect.getinnerframes(etb, context))\n","  File \"/usr/lib/python3.10/inspect.py\", line 1662, in getinnerframes\n","    frameinfo = (tb.tb_frame,) + getframeinfo(tb, context)\n","  File \"/usr/lib/python3.10/inspect.py\", line 1620, in getframeinfo\n","    filename = getsourcefile(frame) or getfile(frame)\n","  File \"/usr/lib/python3.10/inspect.py\", line 829, in getsourcefile\n","    module = getmodule(object, filename)\n","  File \"/usr/lib/python3.10/inspect.py\", line 861, in getmodule\n","    file = getabsfile(object, _filename)\n"]},{"name":"stderr","output_type":"stream","text":["ERROR:root:Internal Python error in the inspect module.\n","Below is the traceback from this internal error.\n","\n"]},{"name":"stdout","output_type":"stream","text":["  File \"/usr/lib/python3.10/inspect.py\", line 845, in getabsfile\n","    return os.path.normcase(os.path.abspath(_filename))\n","  File \"/usr/lib/python3.10/posixpath.py\", line 384, in abspath\n","    cwd = os.getcwd()\n","OSError: [Errno 107] Transport endpoint is not connected\n","Traceback (most recent call last):\n","  File \"/usr/local/lib/python3.10/dist-packages/IPython/core/interactiveshell.py\", line 3553, in run_code\n","    exec(code_obj, self.user_global_ns, self.user_ns)\n","  File \"\u003cipython-input-23-f36854496bb4\u003e\", line 2, in \u003ccell line: 2\u003e\n","    get_ipython().run_line_magic('cd', 'scripts')\n","  File \"/usr/local/lib/python3.10/dist-packages/IPython/core/interactiveshell.py\", line 2418, in run_line_magic\n","    result = fn(*args, **kwargs)\n","  File \"\u003cdecorator-gen-85\u003e\", line 2, in cd\n","  File \"/usr/local/lib/python3.10/dist-packages/IPython/core/magic.py\", line 187, in \u003clambda\u003e\n","    call = lambda f, *a, **k: f(*a, **k)\n","  File \"/usr/local/lib/python3.10/dist-packages/IPython/core/magics/osm.py\", line 342, in cd\n","    oldcwd = os.getcwd()\n","OSError: [Errno 107] Transport endpoint is not connected\n","\n","During handling of the above exception, another exception occurred:\n","\n","Traceback (most recent call last):\n","  File \"/usr/local/lib/python3.10/dist-packages/IPython/core/interactiveshell.py\", line 2099, in showtraceback\n","    stb = value._render_traceback_()\n","AttributeError: 'OSError' object has no attribute '_render_traceback_'\n","\n","During handling of the above exception, another exception occurred:\n","\n","Traceback (most recent call last):\n","  File \"/usr/local/lib/python3.10/dist-packages/IPython/core/interactiveshell.py\", line 3473, in run_ast_nodes\n","    if (await self.run_code(code, result,  async_=asy)):\n","  File \"/usr/local/lib/python3.10/dist-packages/IPython/core/interactiveshell.py\", line 3575, in run_code\n","    self.showtraceback(running_compiled_code=True)\n","  File \"/usr/local/lib/python3.10/dist-packages/IPython/core/interactiveshell.py\", line 2101, in showtraceback\n","    stb = self.InteractiveTB.structured_traceback(etype,\n","  File \"/usr/local/lib/python3.10/dist-packages/IPython/core/ultratb.py\", line 1367, in structured_traceback\n","    return FormattedTB.structured_traceback(\n","  File \"/usr/local/lib/python3.10/dist-packages/IPython/core/ultratb.py\", line 1267, in structured_traceback\n","    return VerboseTB.structured_traceback(\n","  File \"/usr/local/lib/python3.10/dist-packages/IPython/core/ultratb.py\", line 1124, in structured_traceback\n","    formatted_exception = self.format_exception_as_a_whole(etype, evalue, etb, number_of_lines_of_context,\n","  File \"/usr/local/lib/python3.10/dist-packages/IPython/core/ultratb.py\", line 1082, in format_exception_as_a_whole\n","    last_unique, recursion_repeat = find_recursion(orig_etype, evalue, records)\n","  File \"/usr/local/lib/python3.10/dist-packages/IPython/core/ultratb.py\", line 382, in find_recursion\n","    return len(records), 0\n","TypeError: object of type 'NoneType' has no len()\n","\n","During handling of the above exception, another exception occurred:\n","\n","Traceback (most recent call last):\n","  File \"/usr/local/lib/python3.10/dist-packages/IPython/core/interactiveshell.py\", line 2099, in showtraceback\n","    stb = value._render_traceback_()\n","AttributeError: 'TypeError' object has no attribute '_render_traceback_'\n","\n","During handling of the above exception, another exception occurred:\n","\n","Traceback (most recent call last):\n","  File \"/usr/local/lib/python3.10/dist-packages/IPython/core/interactiveshell.py\", line 3030, in _run_cell\n","    return runner(coro)\n","  File \"/usr/local/lib/python3.10/dist-packages/IPython/core/async_helpers.py\", line 78, in _pseudo_sync_runner\n","    coro.send(None)\n","  File \"/usr/local/lib/python3.10/dist-packages/IPython/core/interactiveshell.py\", line 3257, in run_cell_async\n","    has_raised = await self.run_ast_nodes(code_ast.body, cell_name,\n","  File \"/usr/local/lib/python3.10/dist-packages/IPython/core/interactiveshell.py\", line 3492, in run_ast_nodes\n","    self.showtraceback()\n","  File \"/usr/local/lib/python3.10/dist-packages/IPython/core/interactiveshell.py\", line 2101, in showtraceback\n","    stb = self.InteractiveTB.structured_traceback(etype,\n","  File \"/usr/local/lib/python3.10/dist-packages/IPython/core/ultratb.py\", line 1367, in structured_traceback\n","    return FormattedTB.structured_traceback(\n","  File \"/usr/local/lib/python3.10/dist-packages/IPython/core/ultratb.py\", line 1267, in structured_traceback\n","    return VerboseTB.structured_traceback(\n","  File \"/usr/local/lib/python3.10/dist-packages/IPython/core/ultratb.py\", line 1142, in structured_traceback\n","    formatted_exceptions += self.format_exception_as_a_whole(etype, evalue, etb, lines_of_context,\n","  File \"/usr/local/lib/python3.10/dist-packages/IPython/core/ultratb.py\", line 1082, in format_exception_as_a_whole\n","    last_unique, recursion_repeat = find_recursion(orig_etype, evalue, records)\n","  File \"/usr/local/lib/python3.10/dist-packages/IPython/core/ultratb.py\", line 382, in find_recursion\n","    return len(records), 0\n","TypeError: object of type 'NoneType' has no len()\n","\n","During handling of the above exception, another exception occurred:\n","\n","Traceback (most recent call last):\n","  File \"/usr/local/lib/python3.10/dist-packages/IPython/core/interactiveshell.py\", line 2099, in showtraceback\n","    stb = value._render_traceback_()\n","AttributeError: 'TypeError' object has no attribute '_render_traceback_'\n","\n","During handling of the above exception, another exception occurred:\n","\n","Traceback (most recent call last):\n","  File \"/usr/local/lib/python3.10/dist-packages/IPython/core/ultratb.py\", line 1101, in get_records\n","    return _fixed_getinnerframes(etb, number_of_lines_of_context, tb_offset)\n","  File \"/usr/local/lib/python3.10/dist-packages/IPython/core/ultratb.py\", line 248, in wrapped\n","    return f(*args, **kwargs)\n","  File \"/usr/local/lib/python3.10/dist-packages/IPython/core/ultratb.py\", line 281, in _fixed_getinnerframes\n","    records = fix_frame_records_filenames(inspect.getinnerframes(etb, context))\n","  File \"/usr/lib/python3.10/inspect.py\", line 1662, in getinnerframes\n","    frameinfo = (tb.tb_frame,) + getframeinfo(tb, context)\n","  File \"/usr/lib/python3.10/inspect.py\", line 1620, in getframeinfo\n","    filename = getsourcefile(frame) or getfile(frame)\n","  File \"/usr/lib/python3.10/inspect.py\", line 829, in getsourcefile\n","    module = getmodule(object, filename)\n","  File \"/usr/lib/python3.10/inspect.py\", line 861, in getmodule\n","    file = getabsfile(object, _filename)\n","  File \"/usr/lib/python3.10/inspect.py\", line 845, in getabsfile\n","    return os.path.normcase(os.path.abspath(_filename))\n","  File \"/usr/lib/python3.10/posixpath.py\", line 384, in abspath\n","    cwd = os.getcwd()\n","OSError: [Errno 107] Transport endpoint is not connected\n"]}],"source":["import sys, os\n","%cd scripts\n","sys.path.append(os.path.abspath(\"..\"))\n","%run Enh_eval.py --mode infer"]},{"cell_type":"code","execution_count":23,"metadata":{"executionInfo":{"elapsed":33,"status":"ok","timestamp":1715733817229,"user":{"displayName":"Adithyaa seran","userId":"15600754421888670023"},"user_tz":-330},"id":"BpgALzrvdSbo"},"outputs":[],"source":["import os\n","from PIL import Image\n","import matplotlib.pyplot as plt\n","\n","result_folder = \"/content/drive/MyDrive/FYP_APRIL/Resolution_enhancer/exps/quickstart_Enh/test_results\"\n","\n","# Get a list of all files in the folder\n","files = os.listdir(result_folder)\n","\n","# Filter out only the image files (assuming they have common image extensions)\n","image_files = [f for f in files if f.endswith(('.jpg', '.jpeg', '.png', '.gif', '.bmp'))]\n","\n","# Loop through the image files and print them\n","for image_file in image_files:\n","    img_path = os.path.join(result_folder, image_file)\n","    img = Image.open(img_path)\n","    plt.imshow(img)\n","    plt.title(image_file)\n","    plt.axis('off')  # Hide axis\n","    plt.show()\n"]},{"cell_type":"code","execution_count":24,"metadata":{"colab":{"base_uri":"https://localhost:8080/"},"executionInfo":{"elapsed":33,"status":"ok","timestamp":1715733817230,"user":{"displayName":"Adithyaa seran","userId":"15600754421888670023"},"user_tz":-330},"id":"-QAtEQAqdUgW","outputId":"a51c46da-309e-47fd-d8ae-64436ac5c1ac"},"outputs":[{"name":"stdout","output_type":"stream","text":["Processing complete.\n"]}],"source":["import os\n","import cv2\n","\n","# Directory containing images\n","directory = '/content/drive/MyDrive/FYP_APRIL/Resolution_enhancer/exps/quickstart_Enh/test_results'\n","\n","# Iterate through files in the directory\n","for filename in os.listdir(directory):\n","    if filename.endswith('.jpg') or filename.endswith('.png'):  # Check if file is an image\n","        # Load image\n","        image_path = os.path.join(directory, filename)\n","        image = cv2.imread(image_path)\n","\n","        # Get image dimensions\n","        height, width, _ = image.shape\n","\n","        # Crop and resize right half\n","        right_half = image[:, width//2:, :]\n","        resized_image = cv2.resize(right_half, (256, 256))\n","\n","        # Save processed image\n","        output_path = os.path.join(directory,  filename)\n","        cv2.imwrite(output_path, resized_image)\n","\n","print(\"Processing complete.\")\n"]},{"cell_type":"code","execution_count":25,"metadata":{"colab":{"base_uri":"https://localhost:8080/"},"executionInfo":{"elapsed":25,"status":"ok","timestamp":1715733817230,"user":{"displayName":"Adithyaa seran","userId":"15600754421888670023"},"user_tz":-330},"id":"Vvs66zJJdVAQ","outputId":"e04c0101-7cee-4592-d195-573ebb6a0ff8"},"outputs":[{"name":"stdout","output_type":"stream","text":["Images moved successfully.\n"]}],"source":["import os\n","import shutil\n","\n","source_dir = '/content/drive/MyDrive/FYP_APRIL/Resolution_enhancer/exps/quickstart_Enh/test_results'\n","destination_dir = '/content/drive/MyDrive/FYP_APRIL/ImageRestoration/hq_demo/data/datasets/gts/face'\n","\n","# Check if both source and destination directories exist\n","if os.path.exists(source_dir) and os.path.exists(destination_dir):\n","    # Get the list of files in the source directory\n","    files = os.listdir(source_dir)\n","\n","    # Iterate over each file in the source directory\n","    for file_name in files:\n","        # Construct the source and destination file paths\n","        source_file = os.path.join(source_dir, file_name)\n","        destination_file = os.path.join(destination_dir, file_name)\n","\n","        # Move the file from the source to the destination directory\n","        shutil.move(source_file, destination_file)\n","\n","    print(\"Images moved successfully.\")\n","else:\n","    print(\"Source or destination directory does not exist.\")\n"]},{"cell_type":"code","execution_count":25,"metadata":{"executionInfo":{"elapsed":24,"status":"ok","timestamp":1715733817230,"user":{"displayName":"Adithyaa seran","userId":"15600754421888670023"},"user_tz":-330},"id":"9NUXN9tSTYjH"},"outputs":[],"source":[]},{"cell_type":"code","execution_count":null,"metadata":{"colab":{"background_save":true,"base_uri":"https://localhost:8080/"},"id":"Ajf0bogaRWSm"},"outputs":[{"name":"stderr","output_type":"stream","text":["ERROR:root:Internal Python error in the inspect module.\n","Below is the traceback from this internal error.\n","\n","ERROR:root:Internal Python error in the inspect module.\n","Below is the traceback from this internal error.\n","\n","ERROR:root:Internal Python error in the inspect module.\n","Below is the traceback from this internal error.\n","\n"]},{"name":"stdout","output_type":"stream","text":["Traceback (most recent call last):\n","  File \"/usr/local/lib/python3.10/dist-packages/IPython/core/interactiveshell.py\", line 3553, in run_code\n","    exec(code_obj, self.user_global_ns, self.user_ns)\n","  File \"\u003cipython-input-26-6ef6089e6530\u003e\", line 1, in \u003ccell line: 1\u003e\n","    get_ipython().run_line_magic('cd', '/content/drive/MyDrive/FYP_APRIL/')\n","  File \"/usr/local/lib/python3.10/dist-packages/IPython/core/interactiveshell.py\", line 2418, in run_line_magic\n","    result = fn(*args, **kwargs)\n","  File \"\u003cdecorator-gen-85\u003e\", line 2, in cd\n","  File \"/usr/local/lib/python3.10/dist-packages/IPython/core/magic.py\", line 187, in \u003clambda\u003e\n","    call = lambda f, *a, **k: f(*a, **k)\n","  File \"/usr/local/lib/python3.10/dist-packages/IPython/core/magics/osm.py\", line 342, in cd\n","    oldcwd = os.getcwd()\n","OSError: [Errno 107] Transport endpoint is not connected\n","\n","During handling of the above exception, another exception occurred:\n","\n","Traceback (most recent call last):\n","  File \"/usr/local/lib/python3.10/dist-packages/IPython/core/interactiveshell.py\", line 2099, in showtraceback\n","    stb = value._render_traceback_()\n","AttributeError: 'OSError' object has no attribute '_render_traceback_'\n","\n","During handling of the above exception, another exception occurred:\n","\n","Traceback (most recent call last):\n","  File \"/usr/local/lib/python3.10/dist-packages/IPython/core/ultratb.py\", line 1101, in get_records\n","    return _fixed_getinnerframes(etb, number_of_lines_of_context, tb_offset)\n","  File \"/usr/local/lib/python3.10/dist-packages/IPython/core/ultratb.py\", line 248, in wrapped\n","    return f(*args, **kwargs)\n","  File \"/usr/local/lib/python3.10/dist-packages/IPython/core/ultratb.py\", line 281, in _fixed_getinnerframes\n","    records = fix_frame_records_filenames(inspect.getinnerframes(etb, context))\n","  File \"/usr/lib/python3.10/inspect.py\", line 1662, in getinnerframes\n","    frameinfo = (tb.tb_frame,) + getframeinfo(tb, context)\n","  File \"/usr/lib/python3.10/inspect.py\", line 1620, in getframeinfo\n","    filename = getsourcefile(frame) or getfile(frame)\n","  File \"/usr/lib/python3.10/inspect.py\", line 829, in getsourcefile\n","    module = getmodule(object, filename)\n","  File \"/usr/lib/python3.10/inspect.py\", line 861, in getmodule\n","    file = getabsfile(object, _filename)\n","  File \"/usr/lib/python3.10/inspect.py\", line 845, in getabsfile\n","    return os.path.normcase(os.path.abspath(_filename))\n","  File \"/usr/lib/python3.10/posixpath.py\", line 384, in abspath\n","    cwd = os.getcwd()\n","OSError: [Errno 107] Transport endpoint is not connected\n","Traceback (most recent call last):\n","  File \"/usr/local/lib/python3.10/dist-packages/IPython/core/interactiveshell.py\", line 3553, in run_code\n","    exec(code_obj, self.user_global_ns, self.user_ns)\n","  File \"\u003cipython-input-26-6ef6089e6530\u003e\", line 1, in \u003ccell line: 1\u003e\n","    get_ipython().run_line_magic('cd', '/content/drive/MyDrive/FYP_APRIL/')\n","  File \"/usr/local/lib/python3.10/dist-packages/IPython/core/interactiveshell.py\", line 2418, in run_line_magic\n","    result = fn(*args, **kwargs)\n","  File \"\u003cdecorator-gen-85\u003e\", line 2, in cd\n","  File \"/usr/local/lib/python3.10/dist-packages/IPython/core/magic.py\", line 187, in \u003clambda\u003e\n","    call = lambda f, *a, **k: f(*a, **k)\n","  File \"/usr/local/lib/python3.10/dist-packages/IPython/core/magics/osm.py\", line 342, in cd\n","    oldcwd = os.getcwd()\n","OSError: [Errno 107] Transport endpoint is not connected\n","\n","During handling of the above exception, another exception occurred:\n","\n","Traceback (most recent call last):\n","  File \"/usr/local/lib/python3.10/dist-packages/IPython/core/interactiveshell.py\", line 2099, in showtraceback\n","    stb = value._render_traceback_()\n","AttributeError: 'OSError' object has no attribute '_render_traceback_'\n","\n","During handling of the above exception, another exception occurred:\n","\n","Traceback (most recent call last):\n","  File \"/usr/local/lib/python3.10/dist-packages/IPython/core/interactiveshell.py\", line 3473, in run_ast_nodes\n","    if (await self.run_code(code, result,  async_=asy)):\n","  File \"/usr/local/lib/python3.10/dist-packages/IPython/core/interactiveshell.py\", line 3575, in run_code\n","    self.showtraceback(running_compiled_code=True)\n","  File \"/usr/local/lib/python3.10/dist-packages/IPython/core/interactiveshell.py\", line 2101, in showtraceback\n","    stb = self.InteractiveTB.structured_traceback(etype,\n","  File \"/usr/local/lib/python3.10/dist-packages/IPython/core/ultratb.py\", line 1367, in structured_traceback\n","    return FormattedTB.structured_traceback(\n","  File \"/usr/local/lib/python3.10/dist-packages/IPython/core/ultratb.py\", line 1267, in structured_traceback\n","    return VerboseTB.structured_traceback(\n","  File \"/usr/local/lib/python3.10/dist-packages/IPython/core/ultratb.py\", line 1124, in structured_traceback\n","    formatted_exception = self.format_exception_as_a_whole(etype, evalue, etb, number_of_lines_of_context,\n","  File \"/usr/local/lib/python3.10/dist-packages/IPython/core/ultratb.py\", line 1082, in format_exception_as_a_whole\n","    last_unique, recursion_repeat = find_recursion(orig_etype, evalue, records)\n","  File \"/usr/local/lib/python3.10/dist-packages/IPython/core/ultratb.py\", line 382, in find_recursion\n","    return len(records), 0\n","TypeError: object of type 'NoneType' has no len()\n","\n","During handling of the above exception, another exception occurred:\n","\n","Traceback (most recent call last):\n","  File \"/usr/local/lib/python3.10/dist-packages/IPython/core/interactiveshell.py\", line 2099, in showtraceback\n","    stb = value._render_traceback_()\n","AttributeError: 'TypeError' object has no attribute '_render_traceback_'\n","\n","During handling of the above exception, another exception occurred:\n","\n","Traceback (most recent call last):\n","  File \"/usr/local/lib/python3.10/dist-packages/IPython/core/ultratb.py\", line 1101, in get_records\n","    return _fixed_getinnerframes(etb, number_of_lines_of_context, tb_offset)\n","  File \"/usr/local/lib/python3.10/dist-packages/IPython/core/ultratb.py\", line 248, in wrapped\n","    return f(*args, **kwargs)\n","  File \"/usr/local/lib/python3.10/dist-packages/IPython/core/ultratb.py\", line 281, in _fixed_getinnerframes\n","    records = fix_frame_records_filenames(inspect.getinnerframes(etb, context))\n","  File \"/usr/lib/python3.10/inspect.py\", line 1662, in getinnerframes\n","    frameinfo = (tb.tb_frame,) + getframeinfo(tb, context)\n","  File \"/usr/lib/python3.10/inspect.py\", line 1620, in getframeinfo\n","    filename = getsourcefile(frame) or getfile(frame)\n","  File \"/usr/lib/python3.10/inspect.py\", line 829, in getsourcefile\n","    module = getmodule(object, filename)\n","  File \"/usr/lib/python3.10/inspect.py\", line 861, in getmodule\n","    file = getabsfile(object, _filename)\n","  File \"/usr/lib/python3.10/inspect.py\", line 845, in getabsfile\n","    return os.path.normcase(os.path.abspath(_filename))\n","  File \"/usr/lib/python3.10/posixpath.py\", line 384, in abspath\n","    cwd = os.getcwd()\n","OSError: [Errno 107] Transport endpoint is not connected\n","Traceback (most recent call last):\n","  File \"/usr/local/lib/python3.10/dist-packages/IPython/core/interactiveshell.py\", line 3553, in run_code\n","    exec(code_obj, self.user_global_ns, self.user_ns)\n","  File \"\u003cipython-input-26-6ef6089e6530\u003e\", line 1, in \u003ccell line: 1\u003e\n","    get_ipython().run_line_magic('cd', '/content/drive/MyDrive/FYP_APRIL/')\n","  File \"/usr/local/lib/python3.10/dist-packages/IPython/core/interactiveshell.py\", line 2418, in run_line_magic\n","    result = fn(*args, **kwargs)\n","  File \"\u003cdecorator-gen-85\u003e\", line 2, in cd\n","  File \"/usr/local/lib/python3.10/dist-packages/IPython/core/magic.py\", line 187, in \u003clambda\u003e\n","    call = lambda f, *a, **k: f(*a, **k)\n","  File \"/usr/local/lib/python3.10/dist-packages/IPython/core/magics/osm.py\", line 342, in cd\n","    oldcwd = os.getcwd()\n","OSError: [Errno 107] Transport endpoint is not connected\n","\n","During handling of the above exception, another exception occurred:\n","\n","Traceback (most recent call last):\n","  File \"/usr/local/lib/python3.10/dist-packages/IPython/core/interactiveshell.py\", line 2099, in showtraceback\n","    stb = value._render_traceback_()\n","AttributeError: 'OSError' object has no attribute '_render_traceback_'\n","\n","During handling of the above exception, another exception occurred:\n","\n","Traceback (most recent call last):\n","  File \"/usr/local/lib/python3.10/dist-packages/IPython/core/interactiveshell.py\", line 3473, in run_ast_nodes\n","    if (await self.run_code(code, result,  async_=asy)):\n","  File \"/usr/local/lib/python3.10/dist-packages/IPython/core/interactiveshell.py\", line 3575, in run_code\n","    self.showtraceback(running_compiled_code=True)\n","  File \"/usr/local/lib/python3.10/dist-packages/IPython/core/interactiveshell.py\", line 2101, in showtraceback\n","    stb = self.InteractiveTB.structured_traceback(etype,\n","  File \"/usr/local/lib/python3.10/dist-packages/IPython/core/ultratb.py\", line 1367, in structured_traceback\n","    return FormattedTB.structured_traceback(\n","  File \"/usr/local/lib/python3.10/dist-packages/IPython/core/ultratb.py\", line 1267, in structured_traceback\n","    return VerboseTB.structured_traceback(\n","  File \"/usr/local/lib/python3.10/dist-packages/IPython/core/ultratb.py\", line 1124, in structured_traceback\n","    formatted_exception = self.format_exception_as_a_whole(etype, evalue, etb, number_of_lines_of_context,\n","  File \"/usr/local/lib/python3.10/dist-packages/IPython/core/ultratb.py\", line 1082, in format_exception_as_a_whole\n","    last_unique, recursion_repeat = find_recursion(orig_etype, evalue, records)\n","  File \"/usr/local/lib/python3.10/dist-packages/IPython/core/ultratb.py\", line 382, in find_recursion\n","    return len(records), 0\n","TypeError: object of type 'NoneType' has no len()\n","\n","During handling of the above exception, another exception occurred:\n","\n","Traceback (most recent call last):\n","  File \"/usr/local/lib/python3.10/dist-packages/IPython/core/interactiveshell.py\", line 2099, in showtraceback\n","    stb = value._render_traceback_()\n","AttributeError: 'TypeError' object has no attribute '_render_traceback_'\n","\n","During handling of the above exception, another exception occurred:\n","\n","Traceback (most recent call last):\n","  File \"/usr/local/lib/python3.10/dist-packages/IPython/core/interactiveshell.py\", line 3030, in _run_cell\n","    return runner(coro)\n","  File \"/usr/local/lib/python3.10/dist-packages/IPython/core/async_helpers.py\", line 78, in _pseudo_sync_runner\n","    coro.send(None)\n","  File \"/usr/local/lib/python3.10/dist-packages/IPython/core/interactiveshell.py\", line 3257, in run_cell_async\n","    has_raised = await self.run_ast_nodes(code_ast.body, cell_name,\n","  File \"/usr/local/lib/python3.10/dist-packages/IPython/core/interactiveshell.py\", line 3492, in run_ast_nodes\n","    self.showtraceback()\n","  File \"/usr/local/lib/python3.10/dist-packages/IPython/core/interactiveshell.py\", line 2101, in showtraceback\n","    stb = self.InteractiveTB.structured_traceback(etype,\n","  File \"/usr/local/lib/python3.10/dist-packages/IPython/core/ultratb.py\", line 1367, in structured_traceback\n","    return FormattedTB.structured_traceback(\n","  File \"/usr/local/lib/python3.10/dist-packages/IPython/core/ultratb.py\", line 1267, in structured_traceback\n","    return VerboseTB.structured_traceback(\n","  File \"/usr/local/lib/python3.10/dist-packages/IPython/core/ultratb.py\", line 1142, in structured_traceback\n","    formatted_exceptions += self.format_exception_as_a_whole(etype, evalue, etb, lines_of_context,\n","  File \"/usr/local/lib/python3.10/dist-packages/IPython/core/ultratb.py\", line 1082, in format_exception_as_a_whole\n","    last_unique, recursion_repeat = find_recursion(orig_etype, evalue, records)\n","  File \"/usr/local/lib/python3.10/dist-packages/IPython/core/ultratb.py\", line 382, in find_recursion\n","    return len(records), 0\n","TypeError: object of type 'NoneType' has no len()\n","\n","During handling of the above exception, another exception occurred:\n","\n","Traceback (most recent call last):\n","  File \"/usr/local/lib/python3.10/dist-packages/IPython/core/interactiveshell.py\", line 2099, in showtraceback\n","    stb = value._render_traceback_()\n","AttributeError: 'TypeError' object has no attribute '_render_traceback_'\n","\n","During handling of the above exception, another exception occurred:\n","\n","Traceback (most recent call last):\n","  File \"/usr/local/lib/python3.10/dist-packages/IPython/core/ultratb.py\", line 1101, in get_records\n","    return _fixed_getinnerframes(etb, number_of_lines_of_context, tb_offset)\n","  File \"/usr/local/lib/python3.10/dist-packages/IPython/core/ultratb.py\", line 248, in wrapped\n","    return f(*args, **kwargs)\n","  File \"/usr/local/lib/python3.10/dist-packages/IPython/core/ultratb.py\", line 281, in _fixed_getinnerframes\n","    records = fix_frame_records_filenames(inspect.getinnerframes(etb, context))\n","  File \"/usr/lib/python3.10/inspect.py\", line 1662, in getinnerframes\n","    frameinfo = (tb.tb_frame,) + getframeinfo(tb, context)\n","  File \"/usr/lib/python3.10/inspect.py\", line 1620, in getframeinfo\n","    filename = getsourcefile(frame) or getfile(frame)\n","  File \"/usr/lib/python3.10/inspect.py\", line 829, in getsourcefile\n","    module = getmodule(object, filename)\n","  File \"/usr/lib/python3.10/inspect.py\", line 861, in getmodule\n","    file = getabsfile(object, _filename)\n","  File \"/usr/lib/python3.10/inspect.py\", line 845, in getabsfile\n","    return os.path.normcase(os.path.abspath(_filename))\n","  File \"/usr/lib/python3.10/posixpath.py\", line 384, in abspath\n","    cwd = os.getcwd()\n","OSError: [Errno 107] Transport endpoint is not connected\n"]}],"source":["%cd /content/drive/MyDrive/FYP_APRIL/"]},{"cell_type":"code","execution_count":26,"metadata":{"executionInfo":{"elapsed":20,"status":"ok","timestamp":1715733817231,"user":{"displayName":"Adithyaa seran","userId":"15600754421888670023"},"user_tz":-330},"id":"dua5lHyudVL9"},"outputs":[],"source":["# !git clone https://github.com/Adithyaa011/ImageRestoration.git"]},{"cell_type":"code","execution_count":27,"metadata":{"executionInfo":{"elapsed":19,"status":"ok","timestamp":1715733817231,"user":{"displayName":"Adithyaa seran","userId":"15600754421888670023"},"user_tz":-330},"id":"E9eCnWDsdYr6"},"outputs":[],"source":["# !mkdir /content/drive/MyDrive/FYP_APRIL/ImageRestoration/hq_demo/data/pretrained"]},{"cell_type":"code","execution_count":28,"metadata":{"colab":{"base_uri":"https://localhost:8080/"},"executionInfo":{"elapsed":19,"status":"ok","timestamp":1715733817231,"user":{"displayName":"Adithyaa seran","userId":"15600754421888670023"},"user_tz":-330},"id":"KhEUD5dVddm8","outputId":"fc94d2ac-6fdb-427d-a83a-1881efd43ec6"},"outputs":[{"name":"stdout","output_type":"stream","text":["shell-init: error retrieving current directory: getcwd: cannot access parent directories: Transport endpoint is not connected\n","shell-init: error retrieving current directory: getcwd: cannot access parent directories: Transport endpoint is not connected\n","Traceback (most recent call last):\n","  File \"/usr/local/bin/pip3\", line 5, in \u003cmodule\u003e\n","    from pip._internal.cli.main import main\n","  File \"/usr/local/lib/python3.10/dist-packages/pip/_internal/cli/main.py\", line 10, in \u003cmodule\u003e\n","    from pip._internal.cli.autocompletion import autocomplete\n","  File \"/usr/local/lib/python3.10/dist-packages/pip/_internal/cli/autocompletion.py\", line 10, in \u003cmodule\u003e\n","    from pip._internal.cli.main_parser import create_main_parser\n","  File \"/usr/local/lib/python3.10/dist-packages/pip/_internal/cli/main_parser.py\", line 9, in \u003cmodule\u003e\n","    from pip._internal.build_env import get_runnable_pip\n","  File \"/usr/local/lib/python3.10/dist-packages/pip/_internal/build_env.py\", line 19, in \u003cmodule\u003e\n","    from pip._internal.cli.spinners import open_spinner\n","  File \"/usr/local/lib/python3.10/dist-packages/pip/_internal/cli/spinners.py\", line 9, in \u003cmodule\u003e\n","    from pip._internal.utils.logging import get_indentation\n","  File \"/usr/local/lib/python3.10/dist-packages/pip/_internal/utils/logging.py\", line 13, in \u003cmodule\u003e\n","    from pip._vendor.rich.console import (\n","  File \"/usr/local/lib/python3.10/dist-packages/pip/_vendor/rich/__init__.py\", line 17, in \u003cmodule\u003e\n","    _IMPORT_CWD = os.path.abspath(os.getcwd())\n","OSError: [Errno 107] Transport endpoint is not connected\n"]}],"source":["!pip install numpy torch blobfile tqdm pyYaml pillow"]},{"cell_type":"code","execution_count":null,"metadata":{"colab":{"background_save":true,"base_uri":"https://localhost:8080/"},"id":"WydKizAFdghq"},"outputs":[{"name":"stderr","output_type":"stream","text":["ERROR:root:Internal Python error in the inspect module.\n","Below is the traceback from this internal error.\n","\n","ERROR:root:Internal Python error in the inspect module.\n","Below is the traceback from this internal error.\n","\n","ERROR:root:Internal Python error in the inspect module.\n","Below is the traceback from this internal error.\n","\n"]},{"name":"stdout","output_type":"stream","text":["Traceback (most recent call last):\n","  File \"/usr/local/lib/python3.10/dist-packages/IPython/core/interactiveshell.py\", line 3553, in run_code\n","    exec(code_obj, self.user_global_ns, self.user_ns)\n","  File \"\u003cipython-input-29-11f1fd2039e5\u003e\", line 1, in \u003ccell line: 1\u003e\n","    get_ipython().run_line_magic('cd', '/content/drive/MyDrive/FYP_APRIL/ImageRestoration/hq_demo/data/pretrained')\n","  File \"/usr/local/lib/python3.10/dist-packages/IPython/core/interactiveshell.py\", line 2418, in run_line_magic\n","    result = fn(*args, **kwargs)\n","  File \"\u003cdecorator-gen-85\u003e\", line 2, in cd\n","  File \"/usr/local/lib/python3.10/dist-packages/IPython/core/magic.py\", line 187, in \u003clambda\u003e\n","    call = lambda f, *a, **k: f(*a, **k)\n","  File \"/usr/local/lib/python3.10/dist-packages/IPython/core/magics/osm.py\", line 342, in cd\n","    oldcwd = os.getcwd()\n","OSError: [Errno 107] Transport endpoint is not connected\n","\n","During handling of the above exception, another exception occurred:\n","\n","Traceback (most recent call last):\n","  File \"/usr/local/lib/python3.10/dist-packages/IPython/core/interactiveshell.py\", line 2099, in showtraceback\n","    stb = value._render_traceback_()\n","AttributeError: 'OSError' object has no attribute '_render_traceback_'\n","\n","During handling of the above exception, another exception occurred:\n","\n","Traceback (most recent call last):\n","  File \"/usr/local/lib/python3.10/dist-packages/IPython/core/ultratb.py\", line 1101, in get_records\n","    return _fixed_getinnerframes(etb, number_of_lines_of_context, tb_offset)\n","  File \"/usr/local/lib/python3.10/dist-packages/IPython/core/ultratb.py\", line 248, in wrapped\n","    return f(*args, **kwargs)\n","  File \"/usr/local/lib/python3.10/dist-packages/IPython/core/ultratb.py\", line 281, in _fixed_getinnerframes\n","    records = fix_frame_records_filenames(inspect.getinnerframes(etb, context))\n","  File \"/usr/lib/python3.10/inspect.py\", line 1662, in getinnerframes\n","    frameinfo = (tb.tb_frame,) + getframeinfo(tb, context)\n","  File \"/usr/lib/python3.10/inspect.py\", line 1620, in getframeinfo\n","    filename = getsourcefile(frame) or getfile(frame)\n","  File \"/usr/lib/python3.10/inspect.py\", line 829, in getsourcefile\n","    module = getmodule(object, filename)\n","  File \"/usr/lib/python3.10/inspect.py\", line 861, in getmodule\n","    file = getabsfile(object, _filename)\n","  File \"/usr/lib/python3.10/inspect.py\", line 845, in getabsfile\n","    return os.path.normcase(os.path.abspath(_filename))\n","  File \"/usr/lib/python3.10/posixpath.py\", line 384, in abspath\n","    cwd = os.getcwd()\n","OSError: [Errno 107] Transport endpoint is not connected\n","Traceback (most recent call last):\n","  File \"/usr/local/lib/python3.10/dist-packages/IPython/core/interactiveshell.py\", line 3553, in run_code\n","    exec(code_obj, self.user_global_ns, self.user_ns)\n","  File \"\u003cipython-input-29-11f1fd2039e5\u003e\", line 1, in \u003ccell line: 1\u003e\n","    get_ipython().run_line_magic('cd', '/content/drive/MyDrive/FYP_APRIL/ImageRestoration/hq_demo/data/pretrained')\n","  File \"/usr/local/lib/python3.10/dist-packages/IPython/core/interactiveshell.py\", line 2418, in run_line_magic\n","    result = fn(*args, **kwargs)\n","  File \"\u003cdecorator-gen-85\u003e\", line 2, in cd\n","  File \"/usr/local/lib/python3.10/dist-packages/IPython/core/magic.py\", line 187, in \u003clambda\u003e\n","    call = lambda f, *a, **k: f(*a, **k)\n","  File \"/usr/local/lib/python3.10/dist-packages/IPython/core/magics/osm.py\", line 342, in cd\n","    oldcwd = os.getcwd()\n","OSError: [Errno 107] Transport endpoint is not connected\n","\n","During handling of the above exception, another exception occurred:\n","\n","Traceback (most recent call last):\n","  File \"/usr/local/lib/python3.10/dist-packages/IPython/core/interactiveshell.py\", line 2099, in showtraceback\n","    stb = value._render_traceback_()\n","AttributeError: 'OSError' object has no attribute '_render_traceback_'\n","\n","During handling of the above exception, another exception occurred:\n","\n","Traceback (most recent call last):\n","  File \"/usr/local/lib/python3.10/dist-packages/IPython/core/interactiveshell.py\", line 3473, in run_ast_nodes\n","    if (await self.run_code(code, result,  async_=asy)):\n","  File \"/usr/local/lib/python3.10/dist-packages/IPython/core/interactiveshell.py\", line 3575, in run_code\n","    self.showtraceback(running_compiled_code=True)\n","  File \"/usr/local/lib/python3.10/dist-packages/IPython/core/interactiveshell.py\", line 2101, in showtraceback\n","    stb = self.InteractiveTB.structured_traceback(etype,\n","  File \"/usr/local/lib/python3.10/dist-packages/IPython/core/ultratb.py\", line 1367, in structured_traceback\n","    return FormattedTB.structured_traceback(\n","  File \"/usr/local/lib/python3.10/dist-packages/IPython/core/ultratb.py\", line 1267, in structured_traceback\n","    return VerboseTB.structured_traceback(\n","  File \"/usr/local/lib/python3.10/dist-packages/IPython/core/ultratb.py\", line 1124, in structured_traceback\n","    formatted_exception = self.format_exception_as_a_whole(etype, evalue, etb, number_of_lines_of_context,\n","  File \"/usr/local/lib/python3.10/dist-packages/IPython/core/ultratb.py\", line 1082, in format_exception_as_a_whole\n","    last_unique, recursion_repeat = find_recursion(orig_etype, evalue, records)\n","  File \"/usr/local/lib/python3.10/dist-packages/IPython/core/ultratb.py\", line 382, in find_recursion\n","    return len(records), 0\n","TypeError: object of type 'NoneType' has no len()\n","\n","During handling of the above exception, another exception occurred:\n","\n","Traceback (most recent call last):\n","  File \"/usr/local/lib/python3.10/dist-packages/IPython/core/interactiveshell.py\", line 2099, in showtraceback\n","    stb = value._render_traceback_()\n","AttributeError: 'TypeError' object has no attribute '_render_traceback_'\n","\n","During handling of the above exception, another exception occurred:\n","\n","Traceback (most recent call last):\n","  File \"/usr/local/lib/python3.10/dist-packages/IPython/core/ultratb.py\", line 1101, in get_records\n","    return _fixed_getinnerframes(etb, number_of_lines_of_context, tb_offset)\n","  File \"/usr/local/lib/python3.10/dist-packages/IPython/core/ultratb.py\", line 248, in wrapped\n","    return f(*args, **kwargs)\n","  File \"/usr/local/lib/python3.10/dist-packages/IPython/core/ultratb.py\", line 281, in _fixed_getinnerframes\n","    records = fix_frame_records_filenames(inspect.getinnerframes(etb, context))\n","  File \"/usr/lib/python3.10/inspect.py\", line 1662, in getinnerframes\n","    frameinfo = (tb.tb_frame,) + getframeinfo(tb, context)\n","  File \"/usr/lib/python3.10/inspect.py\", line 1620, in getframeinfo\n","    filename = getsourcefile(frame) or getfile(frame)\n","  File \"/usr/lib/python3.10/inspect.py\", line 829, in getsourcefile\n","    module = getmodule(object, filename)\n","  File \"/usr/lib/python3.10/inspect.py\", line 861, in getmodule\n","    file = getabsfile(object, _filename)\n","  File \"/usr/lib/python3.10/inspect.py\", line 845, in getabsfile\n","    return os.path.normcase(os.path.abspath(_filename))\n","  File \"/usr/lib/python3.10/posixpath.py\", line 384, in abspath\n","    cwd = os.getcwd()\n","OSError: [Errno 107] Transport endpoint is not connected\n","Traceback (most recent call last):\n","  File \"/usr/local/lib/python3.10/dist-packages/IPython/core/interactiveshell.py\", line 3553, in run_code\n","    exec(code_obj, self.user_global_ns, self.user_ns)\n","  File \"\u003cipython-input-29-11f1fd2039e5\u003e\", line 1, in \u003ccell line: 1\u003e\n","    get_ipython().run_line_magic('cd', '/content/drive/MyDrive/FYP_APRIL/ImageRestoration/hq_demo/data/pretrained')\n","  File \"/usr/local/lib/python3.10/dist-packages/IPython/core/interactiveshell.py\", line 2418, in run_line_magic\n","    result = fn(*args, **kwargs)\n","  File \"\u003cdecorator-gen-85\u003e\", line 2, in cd\n","  File \"/usr/local/lib/python3.10/dist-packages/IPython/core/magic.py\", line 187, in \u003clambda\u003e\n","    call = lambda f, *a, **k: f(*a, **k)\n","  File \"/usr/local/lib/python3.10/dist-packages/IPython/core/magics/osm.py\", line 342, in cd\n","    oldcwd = os.getcwd()\n","OSError: [Errno 107] Transport endpoint is not connected\n","\n","During handling of the above exception, another exception occurred:\n","\n","Traceback (most recent call last):\n","  File \"/usr/local/lib/python3.10/dist-packages/IPython/core/interactiveshell.py\", line 2099, in showtraceback\n","    stb = value._render_traceback_()\n","AttributeError: 'OSError' object has no attribute '_render_traceback_'\n","\n","During handling of the above exception, another exception occurred:\n","\n","Traceback (most recent call last):\n","  File \"/usr/local/lib/python3.10/dist-packages/IPython/core/interactiveshell.py\", line 3473, in run_ast_nodes\n","    if (await self.run_code(code, result,  async_=asy)):\n","  File \"/usr/local/lib/python3.10/dist-packages/IPython/core/interactiveshell.py\", line 3575, in run_code\n","    self.showtraceback(running_compiled_code=True)\n","  File \"/usr/local/lib/python3.10/dist-packages/IPython/core/interactiveshell.py\", line 2101, in showtraceback\n","    stb = self.InteractiveTB.structured_traceback(etype,\n","  File \"/usr/local/lib/python3.10/dist-packages/IPython/core/ultratb.py\", line 1367, in structured_traceback\n","    return FormattedTB.structured_traceback(\n","  File \"/usr/local/lib/python3.10/dist-packages/IPython/core/ultratb.py\", line 1267, in structured_traceback\n","    return VerboseTB.structured_traceback(\n","  File \"/usr/local/lib/python3.10/dist-packages/IPython/core/ultratb.py\", line 1124, in structured_traceback\n","    formatted_exception = self.format_exception_as_a_whole(etype, evalue, etb, number_of_lines_of_context,\n","  File \"/usr/local/lib/python3.10/dist-packages/IPython/core/ultratb.py\", line 1082, in format_exception_as_a_whole\n","    last_unique, recursion_repeat = find_recursion(orig_etype, evalue, records)\n","  File \"/usr/local/lib/python3.10/dist-packages/IPython/core/ultratb.py\", line 382, in find_recursion\n","    return len(records), 0\n","TypeError: object of type 'NoneType' has no len()\n","\n","During handling of the above exception, another exception occurred:\n","\n","Traceback (most recent call last):\n","  File \"/usr/local/lib/python3.10/dist-packages/IPython/core/interactiveshell.py\", line 2099, in showtraceback\n","    stb = value._render_traceback_()\n","AttributeError: 'TypeError' object has no attribute '_render_traceback_'\n","\n","During handling of the above exception, another exception occurred:\n","\n","Traceback (most recent call last):\n","  File \"/usr/local/lib/python3.10/dist-packages/IPython/core/interactiveshell.py\", line 3030, in _run_cell\n","    return runner(coro)\n","  File \"/usr/local/lib/python3.10/dist-packages/IPython/core/async_helpers.py\", line 78, in _pseudo_sync_runner\n","    coro.send(None)\n","  File \"/usr/local/lib/python3.10/dist-packages/IPython/core/interactiveshell.py\", line 3257, in run_cell_async\n","    has_raised = await self.run_ast_nodes(code_ast.body, cell_name,\n","  File \"/usr/local/lib/python3.10/dist-packages/IPython/core/interactiveshell.py\", line 3492, in run_ast_nodes\n","    self.showtraceback()\n","  File \"/usr/local/lib/python3.10/dist-packages/IPython/core/interactiveshell.py\", line 2101, in showtraceback\n","    stb = self.InteractiveTB.structured_traceback(etype,\n","  File \"/usr/local/lib/python3.10/dist-packages/IPython/core/ultratb.py\", line 1367, in structured_traceback\n","    return FormattedTB.structured_traceback(\n","  File \"/usr/local/lib/python3.10/dist-packages/IPython/core/ultratb.py\", line 1267, in structured_traceback\n","    return VerboseTB.structured_traceback(\n","  File \"/usr/local/lib/python3.10/dist-packages/IPython/core/ultratb.py\", line 1142, in structured_traceback\n","    formatted_exceptions += self.format_exception_as_a_whole(etype, evalue, etb, lines_of_context,\n","  File \"/usr/local/lib/python3.10/dist-packages/IPython/core/ultratb.py\", line 1082, in format_exception_as_a_whole\n","    last_unique, recursion_repeat = find_recursion(orig_etype, evalue, records)\n","  File \"/usr/local/lib/python3.10/dist-packages/IPython/core/ultratb.py\", line 382, in find_recursion\n","    return len(records), 0\n","TypeError: object of type 'NoneType' has no len()\n","\n","During handling of the above exception, another exception occurred:\n","\n","Traceback (most recent call last):\n","  File \"/usr/local/lib/python3.10/dist-packages/IPython/core/interactiveshell.py\", line 2099, in showtraceback\n","    stb = value._render_traceback_()\n","AttributeError: 'TypeError' object has no attribute '_render_traceback_'\n","\n","During handling of the above exception, another exception occurred:\n","\n","Traceback (most recent call last):\n","  File \"/usr/local/lib/python3.10/dist-packages/IPython/core/ultratb.py\", line 1101, in get_records\n","    return _fixed_getinnerframes(etb, number_of_lines_of_context, tb_offset)\n","  File \"/usr/local/lib/python3.10/dist-packages/IPython/core/ultratb.py\", line 248, in wrapped\n","    return f(*args, **kwargs)\n","  File \"/usr/local/lib/python3.10/dist-packages/IPython/core/ultratb.py\", line 281, in _fixed_getinnerframes\n","    records = fix_frame_records_filenames(inspect.getinnerframes(etb, context))\n","  File \"/usr/lib/python3.10/inspect.py\", line 1662, in getinnerframes\n","    frameinfo = (tb.tb_frame,) + getframeinfo(tb, context)\n","  File \"/usr/lib/python3.10/inspect.py\", line 1620, in getframeinfo\n","    filename = getsourcefile(frame) or getfile(frame)\n","  File \"/usr/lib/python3.10/inspect.py\", line 829, in getsourcefile\n","    module = getmodule(object, filename)\n","  File \"/usr/lib/python3.10/inspect.py\", line 861, in getmodule\n","    file = getabsfile(object, _filename)\n","  File \"/usr/lib/python3.10/inspect.py\", line 845, in getabsfile\n","    return os.path.normcase(os.path.abspath(_filename))\n","  File \"/usr/lib/python3.10/posixpath.py\", line 384, in abspath\n","    cwd = os.getcwd()\n","OSError: [Errno 107] Transport endpoint is not connected\n"]}],"source":["%cd /content/drive/MyDrive/FYP_APRIL/ImageRestoration/hq_demo/data/pretrained"]},{"cell_type":"code","execution_count":null,"metadata":{"colab":{"base_uri":"https://localhost:8080/"},"id":"qgA4HI9ydipQ","outputId":"d5a73c24-d0db-47cb-a029-b4fb74971171"},"outputs":[{"name":"stdout","output_type":"stream","text":["shell-init: error retrieving current directory: getcwd: cannot access parent directories: Transport endpoint is not connected\n"]}],"source":["!gdown https://drive.google.com/uc?id=1norNWWGYP3EZ_o05DmoW1ryKuKMmhlCX"]},{"cell_type":"code","execution_count":null,"metadata":{"colab":{"background_save":true},"id":"3hsy7sr6dkhS"},"outputs":[{"name":"stderr","output_type":"stream","text":["ERROR:root:Internal Python error in the inspect module.\n","Below is the traceback from this internal error.\n","\n","ERROR:root:Internal Python error in the inspect module.\n","Below is the traceback from this internal error.\n","\n","ERROR:root:Internal Python error in the inspect module.\n","Below is the traceback from this internal error.\n","\n"]},{"name":"stdout","output_type":"stream","text":["Traceback (most recent call last):\n","  File \"/usr/local/lib/python3.10/dist-packages/IPython/core/interactiveshell.py\", line 3553, in run_code\n","    exec(code_obj, self.user_global_ns, self.user_ns)\n","  File \"\u003cipython-input-30-d3c9c745ef13\u003e\", line 1, in \u003ccell line: 1\u003e\n","    get_ipython().run_line_magic('cd', '/content/drive/MyDrive/FYP_APRIL/ImageRestoration/hq_demo')\n","  File \"/usr/local/lib/python3.10/dist-packages/IPython/core/interactiveshell.py\", line 2418, in run_line_magic\n","    result = fn(*args, **kwargs)\n","  File \"\u003cdecorator-gen-85\u003e\", line 2, in cd\n","  File \"/usr/local/lib/python3.10/dist-packages/IPython/core/magic.py\", line 187, in \u003clambda\u003e\n","    call = lambda f, *a, **k: f(*a, **k)\n","  File \"/usr/local/lib/python3.10/dist-packages/IPython/core/magics/osm.py\", line 342, in cd\n","    oldcwd = os.getcwd()\n","OSError: [Errno 107] Transport endpoint is not connected\n","\n","During handling of the above exception, another exception occurred:\n","\n","Traceback (most recent call last):\n","  File \"/usr/local/lib/python3.10/dist-packages/IPython/core/interactiveshell.py\", line 2099, in showtraceback\n","    stb = value._render_traceback_()\n","AttributeError: 'OSError' object has no attribute '_render_traceback_'\n","\n","During handling of the above exception, another exception occurred:\n","\n","Traceback (most recent call last):\n","  File \"/usr/local/lib/python3.10/dist-packages/IPython/core/ultratb.py\", line 1101, in get_records\n","    return _fixed_getinnerframes(etb, number_of_lines_of_context, tb_offset)\n","  File \"/usr/local/lib/python3.10/dist-packages/IPython/core/ultratb.py\", line 248, in wrapped\n","    return f(*args, **kwargs)\n","  File \"/usr/local/lib/python3.10/dist-packages/IPython/core/ultratb.py\", line 281, in _fixed_getinnerframes\n","    records = fix_frame_records_filenames(inspect.getinnerframes(etb, context))\n","  File \"/usr/lib/python3.10/inspect.py\", line 1662, in getinnerframes\n","    frameinfo = (tb.tb_frame,) + getframeinfo(tb, context)\n","  File \"/usr/lib/python3.10/inspect.py\", line 1620, in getframeinfo\n","    filename = getsourcefile(frame) or getfile(frame)\n","  File \"/usr/lib/python3.10/inspect.py\", line 829, in getsourcefile\n","    module = getmodule(object, filename)\n","  File \"/usr/lib/python3.10/inspect.py\", line 861, in getmodule\n","    file = getabsfile(object, _filename)\n","  File \"/usr/lib/python3.10/inspect.py\", line 845, in getabsfile\n","    return os.path.normcase(os.path.abspath(_filename))\n","  File \"/usr/lib/python3.10/posixpath.py\", line 384, in abspath\n","    cwd = os.getcwd()\n","OSError: [Errno 107] Transport endpoint is not connected\n","Traceback (most recent call last):\n","  File \"/usr/local/lib/python3.10/dist-packages/IPython/core/interactiveshell.py\", line 3553, in run_code\n","    exec(code_obj, self.user_global_ns, self.user_ns)\n","  File \"\u003cipython-input-30-d3c9c745ef13\u003e\", line 1, in \u003ccell line: 1\u003e\n","    get_ipython().run_line_magic('cd', '/content/drive/MyDrive/FYP_APRIL/ImageRestoration/hq_demo')\n","  File \"/usr/local/lib/python3.10/dist-packages/IPython/core/interactiveshell.py\", line 2418, in run_line_magic\n","    result = fn(*args, **kwargs)\n","  File \"\u003cdecorator-gen-85\u003e\", line 2, in cd\n","  File \"/usr/local/lib/python3.10/dist-packages/IPython/core/magic.py\", line 187, in \u003clambda\u003e\n","    call = lambda f, *a, **k: f(*a, **k)\n","  File \"/usr/local/lib/python3.10/dist-packages/IPython/core/magics/osm.py\", line 342, in cd\n","    oldcwd = os.getcwd()\n","OSError: [Errno 107] Transport endpoint is not connected\n","\n","During handling of the above exception, another exception occurred:\n","\n","Traceback (most recent call last):\n","  File \"/usr/local/lib/python3.10/dist-packages/IPython/core/interactiveshell.py\", line 2099, in showtraceback\n","    stb = value._render_traceback_()\n","AttributeError: 'OSError' object has no attribute '_render_traceback_'\n","\n","During handling of the above exception, another exception occurred:\n","\n","Traceback (most recent call last):\n","  File \"/usr/local/lib/python3.10/dist-packages/IPython/core/interactiveshell.py\", line 3473, in run_ast_nodes\n","    if (await self.run_code(code, result,  async_=asy)):\n","  File \"/usr/local/lib/python3.10/dist-packages/IPython/core/interactiveshell.py\", line 3575, in run_code\n","    self.showtraceback(running_compiled_code=True)\n","  File \"/usr/local/lib/python3.10/dist-packages/IPython/core/interactiveshell.py\", line 2101, in showtraceback\n","    stb = self.InteractiveTB.structured_traceback(etype,\n","  File \"/usr/local/lib/python3.10/dist-packages/IPython/core/ultratb.py\", line 1367, in structured_traceback\n","    return FormattedTB.structured_traceback(\n","  File \"/usr/local/lib/python3.10/dist-packages/IPython/core/ultratb.py\", line 1267, in structured_traceback\n","    return VerboseTB.structured_traceback(\n","  File \"/usr/local/lib/python3.10/dist-packages/IPython/core/ultratb.py\", line 1124, in structured_traceback\n","    formatted_exception = self.format_exception_as_a_whole(etype, evalue, etb, number_of_lines_of_context,\n","  File \"/usr/local/lib/python3.10/dist-packages/IPython/core/ultratb.py\", line 1082, in format_exception_as_a_whole\n","    last_unique, recursion_repeat = find_recursion(orig_etype, evalue, records)\n","  File \"/usr/local/lib/python3.10/dist-packages/IPython/core/ultratb.py\", line 382, in find_recursion\n","    return len(records), 0\n","TypeError: object of type 'NoneType' has no len()\n","\n","During handling of the above exception, another exception occurred:\n","\n","Traceback (most recent call last):\n","  File \"/usr/local/lib/python3.10/dist-packages/IPython/core/interactiveshell.py\", line 2099, in showtraceback\n","    stb = value._render_traceback_()\n","AttributeError: 'TypeError' object has no attribute '_render_traceback_'\n","\n","During handling of the above exception, another exception occurred:\n","\n","Traceback (most recent call last):\n","  File \"/usr/local/lib/python3.10/dist-packages/IPython/core/ultratb.py\", line 1101, in get_records\n","    return _fixed_getinnerframes(etb, number_of_lines_of_context, tb_offset)\n","  File \"/usr/local/lib/python3.10/dist-packages/IPython/core/ultratb.py\", line 248, in wrapped\n","    return f(*args, **kwargs)\n","  File \"/usr/local/lib/python3.10/dist-packages/IPython/core/ultratb.py\", line 281, in _fixed_getinnerframes\n","    records = fix_frame_records_filenames(inspect.getinnerframes(etb, context))\n","  File \"/usr/lib/python3.10/inspect.py\", line 1662, in getinnerframes\n","    frameinfo = (tb.tb_frame,) + getframeinfo(tb, context)\n","  File \"/usr/lib/python3.10/inspect.py\", line 1620, in getframeinfo\n","    filename = getsourcefile(frame) or getfile(frame)\n","  File \"/usr/lib/python3.10/inspect.py\", line 829, in getsourcefile\n","    module = getmodule(object, filename)\n","  File \"/usr/lib/python3.10/inspect.py\", line 861, in getmodule\n","    file = getabsfile(object, _filename)\n","  File \"/usr/lib/python3.10/inspect.py\", line 845, in getabsfile\n","    return os.path.normcase(os.path.abspath(_filename))\n","  File \"/usr/lib/python3.10/posixpath.py\", line 384, in abspath\n","    cwd = os.getcwd()\n","OSError: [Errno 107] Transport endpoint is not connected\n","Traceback (most recent call last):\n","  File \"/usr/local/lib/python3.10/dist-packages/IPython/core/interactiveshell.py\", line 3553, in run_code\n","    exec(code_obj, self.user_global_ns, self.user_ns)\n","  File \"\u003cipython-input-30-d3c9c745ef13\u003e\", line 1, in \u003ccell line: 1\u003e\n","    get_ipython().run_line_magic('cd', '/content/drive/MyDrive/FYP_APRIL/ImageRestoration/hq_demo')\n","  File \"/usr/local/lib/python3.10/dist-packages/IPython/core/interactiveshell.py\", line 2418, in run_line_magic\n","    result = fn(*args, **kwargs)\n","  File \"\u003cdecorator-gen-85\u003e\", line 2, in cd\n","  File \"/usr/local/lib/python3.10/dist-packages/IPython/core/magic.py\", line 187, in \u003clambda\u003e\n","    call = lambda f, *a, **k: f(*a, **k)\n","  File \"/usr/local/lib/python3.10/dist-packages/IPython/core/magics/osm.py\", line 342, in cd\n","    oldcwd = os.getcwd()\n","OSError: [Errno 107] Transport endpoint is not connected\n","\n","During handling of the above exception, another exception occurred:\n","\n","Traceback (most recent call last):\n","  File \"/usr/local/lib/python3.10/dist-packages/IPython/core/interactiveshell.py\", line 2099, in showtraceback\n","    stb = value._render_traceback_()\n","AttributeError: 'OSError' object has no attribute '_render_traceback_'\n","\n","During handling of the above exception, another exception occurred:\n","\n","Traceback (most recent call last):\n","  File \"/usr/local/lib/python3.10/dist-packages/IPython/core/interactiveshell.py\", line 3473, in run_ast_nodes\n","    if (await self.run_code(code, result,  async_=asy)):\n","  File \"/usr/local/lib/python3.10/dist-packages/IPython/core/interactiveshell.py\", line 3575, in run_code\n","    self.showtraceback(running_compiled_code=True)\n","  File \"/usr/local/lib/python3.10/dist-packages/IPython/core/interactiveshell.py\", line 2101, in showtraceback\n","    stb = self.InteractiveTB.structured_traceback(etype,\n","  File \"/usr/local/lib/python3.10/dist-packages/IPython/core/ultratb.py\", line 1367, in structured_traceback\n","    return FormattedTB.structured_traceback(\n","  File \"/usr/local/lib/python3.10/dist-packages/IPython/core/ultratb.py\", line 1267, in structured_traceback\n","    return VerboseTB.structured_traceback(\n","  File \"/usr/local/lib/python3.10/dist-packages/IPython/core/ultratb.py\", line 1124, in structured_traceback\n","    formatted_exception = self.format_exception_as_a_whole(etype, evalue, etb, number_of_lines_of_context,\n","  File \"/usr/local/lib/python3.10/dist-packages/IPython/core/ultratb.py\", line 1082, in format_exception_as_a_whole\n","    last_unique, recursion_repeat = find_recursion(orig_etype, evalue, records)\n","  File \"/usr/local/lib/python3.10/dist-packages/IPython/core/ultratb.py\", line 382, in find_recursion\n","    return len(records), 0\n","TypeError: object of type 'NoneType' has no len()\n","\n","During handling of the above exception, another exception occurred:\n","\n","Traceback (most recent call last):\n","  File \"/usr/local/lib/python3.10/dist-packages/IPython/core/interactiveshell.py\", line 2099, in showtraceback\n","    stb = value._render_traceback_()\n","AttributeError: 'TypeError' object has no attribute '_render_traceback_'\n","\n","During handling of the above exception, another exception occurred:\n","\n","Traceback (most recent call last):\n","  File \"/usr/local/lib/python3.10/dist-packages/IPython/core/interactiveshell.py\", line 3030, in _run_cell\n","    return runner(coro)\n","  File \"/usr/local/lib/python3.10/dist-packages/IPython/core/async_helpers.py\", line 78, in _pseudo_sync_runner\n","    coro.send(None)\n","  File \"/usr/local/lib/python3.10/dist-packages/IPython/core/interactiveshell.py\", line 3257, in run_cell_async\n","    has_raised = await self.run_ast_nodes(code_ast.body, cell_name,\n","  File \"/usr/local/lib/python3.10/dist-packages/IPython/core/interactiveshell.py\", line 3492, in run_ast_nodes\n","    self.showtraceback()\n","  File \"/usr/local/lib/python3.10/dist-packages/IPython/core/interactiveshell.py\", line 2101, in showtraceback\n","    stb = self.InteractiveTB.structured_traceback(etype,\n","  File \"/usr/local/lib/python3.10/dist-packages/IPython/core/ultratb.py\", line 1367, in structured_traceback\n","    return FormattedTB.structured_traceback(\n","  File \"/usr/local/lib/python3.10/dist-packages/IPython/core/ultratb.py\", line 1267, in structured_traceback\n","    return VerboseTB.structured_traceback(\n","  File \"/usr/local/lib/python3.10/dist-packages/IPython/core/ultratb.py\", line 1142, in structured_traceback\n","    formatted_exceptions += self.format_exception_as_a_whole(etype, evalue, etb, lines_of_context,\n","  File \"/usr/local/lib/python3.10/dist-packages/IPython/core/ultratb.py\", line 1082, in format_exception_as_a_whole\n","    last_unique, recursion_repeat = find_recursion(orig_etype, evalue, records)\n","  File \"/usr/local/lib/python3.10/dist-packages/IPython/core/ultratb.py\", line 382, in find_recursion\n","    return len(records), 0\n","TypeError: object of type 'NoneType' has no len()\n","\n","During handling of the above exception, another exception occurred:\n","\n","Traceback (most recent call last):\n","  File \"/usr/local/lib/python3.10/dist-packages/IPython/core/interactiveshell.py\", line 2099, in showtraceback\n","    stb = value._render_traceback_()\n","AttributeError: 'TypeError' object has no attribute '_render_traceback_'\n","\n","During handling of the above exception, another exception occurred:\n","\n","Traceback (most recent call last):\n","  File \"/usr/local/lib/python3.10/dist-packages/IPython/core/ultratb.py\", line 1101, in get_records\n","    return _fixed_getinnerframes(etb, number_of_lines_of_context, tb_offset)\n","  File \"/usr/local/lib/python3.10/dist-packages/IPython/core/ultratb.py\", line 248, in wrapped\n","    return f(*args, **kwargs)\n","  File \"/usr/local/lib/python3.10/dist-packages/IPython/core/ultratb.py\", line 281, in _fixed_getinnerframes\n","    records = fix_frame_records_filenames(inspect.getinnerframes(etb, context))\n","  File \"/usr/lib/python3.10/inspect.py\", line 1662, in getinnerframes\n","    frameinfo = (tb.tb_frame,) + getframeinfo(tb, context)\n","  File \"/usr/lib/python3.10/inspect.py\", line 1620, in getframeinfo\n","    filename = getsourcefile(frame) or getfile(frame)\n","  File \"/usr/lib/python3.10/inspect.py\", line 829, in getsourcefile\n","    module = getmodule(object, filename)\n","  File \"/usr/lib/python3.10/inspect.py\", line 861, in getmodule\n","    file = getabsfile(object, _filename)\n","  File \"/usr/lib/python3.10/inspect.py\", line 845, in getabsfile\n","    return os.path.normcase(os.path.abspath(_filename))\n","  File \"/usr/lib/python3.10/posixpath.py\", line 384, in abspath\n","    cwd = os.getcwd()\n","OSError: [Errno 107] Transport endpoint is not connected\n"]}],"source":["%cd /content/drive/MyDrive/FYP_APRIL/ImageRestoration/hq_demo"]},{"cell_type":"code","execution_count":null,"metadata":{"id":"A3VYZYkjdmfm"},"outputs":[],"source":["!python main.py --config confs/face256.yml --path_y data/datasets/gts/face/0.png --deg \"inpainting\" -i face"]},{"cell_type":"code","execution_count":null,"metadata":{"id":"htAyzclhWtwH"},"outputs":[],"source":["# import glob\n","# import os\n","\n","# # Folder path\n","# folder_path = \"data/datasets/gts/face/\"\n","\n","# # Get all image file paths in the folder\n","# image_files = glob.glob(folder_path + \"*.png\")\n","\n","# # Iterate over each image file path\n","# for image_file in image_files:\n","#     print(\"Processing:\", image_file)\n","#     # Extract the filename without the path\n","#     filename = os.path.basename(image_file)\n","#     # Run your command substituting the filename\n","#     !python main.py --config confs/face256.yml --path_y {image_file} --deg \"inpainting\" -i face\n","\n"]}],"metadata":{"accelerator":"GPU","colab":{"gpuType":"T4","machine_shape":"hm","name":"","version":""},"kernelspec":{"display_name":"Python 3","name":"python3"},"language_info":{"name":"python"}},"nbformat":4,"nbformat_minor":0}